Workbook

Sheet HISTORICO GERAL
A1: DATA EXPORTAÇÃO | B1: NOME | C1: SUBPREFEITURA* | D1: SETOR* | E1: SELIMP* | F1: DIAS DE EXECUÇÃO * | G1: STATUS COMUNICAÇÃO | H1: BATERIA | I1: ÚLTIMA COMUNICAÇÃO
A2: 46009 | B2: SMSUB-LUTOCAR-03-0002 | C2: =IFERROR( INDEX(#REF!,MATCH($E2,#REF!,0)), IFERROR( INDEX('SETORES VARRIÇÃO'!$A:$A,MATCH($E2,'SETORES VARRIÇÃO'!$H:$H,0)), IFERROR( INDEX(#REF!,MATCH($E2,#REF!,0)), INDEX(#REF!,MATCH($E2,#REF!,0)) ))) -> JT | D2: =IFERROR( INDEX(#REF!,MATCH($E2,#REF!,0)), IFERROR( INDEX('SETORES VARRIÇÃO'!$B:$B,MATCH($E2,'SETORES VARRIÇÃO'!$H:$H,0)), IFERROR( INDEX(#REF!,MATCH($E2,#REF!,0)), INDEX(#REF!,MATCH($E2,#REF!,0)) ))) -> JT10303VJ0025 | E2: =SUBSTITUTE(B2,"SMSUB-LUTOCAR-","") -> 03-0002 | F2: =IFERROR( INDEX(#REF!,MATCH($E2,#REF!,0)), IFERROR( INDEX('SETORES VARRIÇÃO'!$F:$F,MATCH($E2,'SETORES VARRIÇÃO'!$H:$H,0)), IFERROR( INDEX(#REF!,MATCH($E2,#REF!,0)), INDEX(#REF!,MATCH($E2,#REF!,0)) ))) -> Terça/Sexta | G2: OFF | H2: 100% (Bateria desatualizada) | I2: 06/12/2025 17:00:15
A3: 46009 | B3: SMSUB-LUTOCAR-03-0004 | C3: =IFERROR( INDEX(#REF!,MATCH($E3,#REF!,0)), IFERROR( INDEX('SETORES VARRIÇÃO'!$A:$A,MATCH($E3,'SETORES VARRIÇÃO'!$H:$H,0)), IFERROR( INDEX(#REF!,MATCH($E3,#REF!,0)), INDEX(#REF!,MATCH($E3,#REF!,0)) ))) -> JT | D3: =IFERROR( INDEX(#REF!,MATCH($E3,#REF!,0)), IFERROR( INDEX('SETORES VARRIÇÃO'!$B:$B,MATCH($E3,'SETORES VARRIÇÃO'!$H:$H,0)), IFERROR( INDEX(#REF!,MATCH($E3,#REF!,0)), INDEX(#REF!,MATCH($E3,#REF!,0)) ))) -> JT10304VJ0059 | E3: =SUBSTITUTE(B3,"SMSUB-LUTOCAR-","") -> 03-0004 | F3: =IFERROR( INDEX(#REF!,MATCH($E3,#REF!,0)), IFERROR( INDEX('SETORES VARRIÇÃO'!$F:$F,MATCH($E3,'SETORES VARRIÇÃO'!$H:$H,0)), IFERROR( INDEX(#REF!,MATCH($E3,#REF!,0)), INDEX(#REF!,MATCH($E3,#REF!,0)) ))) -> Quarta/Sábado | G3: OFF | H3: 100% (Bateria desatualizada) | I3: 06/12/2025 17:21:31
A4: 46009 | B4: SMSUB-LUTOCAR-03-0005 | C4: =IFERROR( INDEX(#REF!,MATCH($E4,#REF!,0)), IFERROR( INDEX('SETORES VARRIÇÃO'!$A:$A,MATCH($E4,'SETORES VARRIÇÃO'!$H:$H,0)), IFERROR( INDEX(#REF!,MATCH($E4,#REF!,0)), INDEX(#REF!,MATCH($E4,#REF!,0)) ))) -> JT | D4: =IFERROR( INDEX(#REF!,MATCH($E4,#REF!,0)), IFERROR( INDEX('SETORES VARRIÇÃO'!$B:$B,MATCH($E4,'SETORES VARRIÇÃO'!$H:$H,0)), IFERROR( INDEX(#REF!,MATCH($E4,#REF!,0)), INDEX(#REF!,MATCH($E4,#REF!,0)) ))) -> JT10202VJ0054 | E4: =SUBSTITUTE(B4,"SMSUB-LUTOCAR-","") -> 03-0005 | F4: =IFERROR( INDEX(#REF!,MATCH($E4,#REF!,0)), IFERROR( INDEX('SETORES VARRIÇÃO'!$F:$F,MATCH($E4,'SETORES VARRIÇÃO'!$H:$H,0)), IFERROR( INDEX(#REF!,MATCH($E4,#REF!,0)), INDEX(#REF!,MATCH($E4,#REF!,0)) ))) -> Segunda/Quarta/Sexta | G4: OFF | H4: 100% (Bateria desatualizada) | I4: 04/12/2025 08:25:30
A5: 46009 | B5: SMSUB-LUTOCAR-03-0008 | C5: =IFERROR( INDEX(#REF!,MATCH($E5,#REF!,0)), IFERROR( INDEX('SETORES VARRIÇÃO'!$A:$A,MATCH($E5,'SETORES VARRIÇÃO'!$H:$H,0)), IFERROR( INDEX(#REF!,MATCH($E5,#REF!,0)), INDEX(#REF!,MATCH($E5,#REF!,0)) ))) -> JT | D5: =IFERROR( INDEX(#REF!,MATCH($E5,#REF!,0)), IFERROR( INDEX('SETORES VARRIÇÃO'!$B:$B,MATCH($E5,'SETORES VARRIÇÃO'!$H:$H,0)), IFERROR( INDEX(#REF!,MATCH($E5,#REF!,0)), INDEX(#REF!,MATCH($E5,#REF!,0)) ))) -> JT10303VJ0036 | E5: =SUBSTITUTE(B5,"SMSUB-LUTOCAR-","") -> 03-0008 | F5: =IFERROR( INDEX(#REF!,MATCH($E5,#REF!,0)), IFERROR( INDEX('SETORES VARRIÇÃO'!$F:$F,MATCH($E5,'SETORES VARRIÇÃO'!$H:$H,0)), IFERROR( INDEX(#REF!,MATCH($E5,#REF!,0)), INDEX(#REF!,MATCH($E5,#REF!,0)) ))) -> Terça/Sexta | G5: OFF | H5: 100% (Bateria desatualizada) | I5: 12/12/2025 12:17:31
A6: 46009 | B6: SMSUB-LUTOCAR-03-0009 | C6: =IFERROR( INDEX(#REF!,MATCH($E6,#REF!,0)), IFERROR( INDEX('SETORES VARRIÇÃO'!$A:$A,MATCH($E6,'SETORES VARRIÇÃO'!$H:$H,0)), IFERROR( INDEX(#REF!,MATCH($E6,#REF!,0)), INDEX(#REF!,MATCH($E6,#REF!,0)) ))) -> MG | D6: =IFERROR( INDEX(#REF!,MATCH($E6,#REF!,0)), IFERROR( INDEX('SETORES VARRIÇÃO'!$B:$B,MATCH($E6,'SETORES VARRIÇÃO'!$H:$H,0)), IFERROR( INDEX(#REF!,MATCH($E6,#REF!,0)), INDEX(#REF!,MATCH($E6,#REF!,0)) ))) -> MG10101VJ0009 | E6: =SUBSTITUTE(B6,"SMSUB-LUTOCAR-","") -> 03-0009 | F6: =IFERROR( INDEX(#REF!,MATCH($E6,#REF!,0)), IFERROR( INDEX('SETORES VARRIÇÃO'!$F:$F,MATCH($E6,'SETORES VARRIÇÃO'!$H:$H,0)), IFERROR( INDEX(#REF!,MATCH($E6,#REF!,0)), INDEX(#REF!,MATCH($E6,#REF!,0)) ))) -> Segunda a Domingo | G6: OFF | H6: 100% (Bateria desatualizada) | I6: 05/12/2025 02:08:42
A7: 46009 | B7: SMSUB-LUTOCAR-03-0012 | C7: =IFERROR( INDEX(#REF!,MATCH($E7,#REF!,0)), IFERROR( INDEX('SETORES VARRIÇÃO'!$A:$A,MATCH($E7,'SETORES VARRIÇÃO'!$H:$H,0)), IFERROR( INDEX(#REF!,MATCH($E7,#REF!,0)), INDEX(#REF!,MATCH($E7,#REF!,0)) ))) -> CV | D7: =IFERROR( INDEX(#REF!,MATCH($E7,#REF!,0)), IFERROR( INDEX('SETORES VARRIÇÃO'!$B:$B,MATCH($E7,'SETORES VARRIÇÃO'!$H:$H,0)), IFERROR( INDEX(#REF!,MATCH($E7,#REF!,0)), INDEX(#REF!,MATCH($E7,#REF!,0)) ))) -> CV10203VJ0052 | E7: =SUBSTITUTE(B7,"SMSUB-LUTOCAR-","") -> 03-0012 | F7: =IFERROR( INDEX(#REF!,MATCH($E7,#REF!,0)), IFERROR( INDEX('SETORES VARRIÇÃO'!$F:$F,MATCH($E7,'SETORES VARRIÇÃO'!$H:$H,0)), IFERROR( INDEX(#REF!,MATCH($E7,#REF!,0)), INDEX(#REF!,MATCH($E7,#REF!,0)) ))) -> Terça/Quinta/Sábado | G7: OFF | H7: 100% (Bateria desatualizada) | I7: 06/12/2025 21:48:36
A8: 46009 | B8: SMSUB-LUTOCAR-03-0013 | C8: =IFERROR( INDEX(#REF!,MATCH($E8,#REF!,0)), IFERROR( INDEX('SETORES VARRIÇÃO'!$A:$A,MATCH($E8,'SETORES VARRIÇÃO'!$H:$H,0)), IFERROR( INDEX(#REF!,MATCH($E8,#REF!,0)), INDEX(#REF!,MATCH($E8,#REF!,0)) ))) -> MG | D8: =IFERROR( INDEX(#REF!,MATCH($E8,#REF!,0)), IFERROR( INDEX('SETORES VARRIÇÃO'!$B:$B,MATCH($E8,'SETORES VARRIÇÃO'!$H:$H,0)), IFERROR( INDEX(#REF!,MATCH($E8,#REF!,0)), INDEX(#REF!,MATCH($E8,#REF!,0)) ))) -> MG10101VJ0013 | E8: =SUBSTITUTE(B8,"SMSUB-LUTOCAR-","") -> 03-0013 | F8: =IFERROR( INDEX(#REF!,MATCH($E8,#REF!,0)), IFERROR( INDEX('SETORES VARRIÇÃO'!$F:$F,MATCH($E8,'SETORES VARRIÇÃO'!$H:$H,0)), IFERROR( INDEX(#REF!,MATCH($E8,#REF!,0)), INDEX(#REF!,MATCH($E8,#REF!,0)) ))) -> Segunda a Domingo | G8: OFF | H8: 100% (Bateria desatualizada) | I8: 05/12/2025 13:28:17
A9: 46009 | B9: SMSUB-LUTOCAR-03-0014 | C9: =IFERROR( INDEX(#REF!,MATCH($E9,#REF!,0)), IFERROR( INDEX('SETORES VARRIÇÃO'!$A:$A,MATCH($E9,'SETORES VARRIÇÃO'!$H:$H,0)), IFERROR( INDEX(#REF!,MATCH($E9,#REF!,0)), INDEX(#REF!,MATCH($E9,#REF!,0)) ))) -> JT | D9: =IFERROR( INDEX(#REF!,MATCH($E9,#REF!,0)), IFERROR( INDEX('SETORES VARRIÇÃO'!$B:$B,MATCH($E9,'SETORES VARRIÇÃO'!$H:$H,0)), IFERROR( INDEX(#REF!,MATCH($E9,#REF!,0)), INDEX(#REF!,MATCH($E9,#REF!,0)) ))) -> JT10302VJ0011 | E9: =SUBSTITUTE(B9,"SMSUB-LUTOCAR-","") -> 03-0014 | F9: =IFERROR( INDEX(#REF!,MATCH($E9,#REF!,0)), IFERROR( INDEX('SETORES VARRIÇÃO'!$F:$F,MATCH($E9,'SETORES VARRIÇÃO'!$H:$H,0)), IFERROR( INDEX(#REF!,MATCH($E9,#REF!,0)), INDEX(#REF!,MATCH($E9,#REF!,0)) ))) -> Segunda/Quinta | G9: OFF | H9: 100% (Bateria desatualizada) | I9: 05/12/2025 13:25:11
A10: 46009 | B10: SMSUB-LUTOCAR-03-0017 | C10: =IFERROR( INDEX(#REF!,MATCH($E10,#REF!,0)), IFERROR( INDEX('SETORES VARRIÇÃO'!$A:$A,MATCH($E10,'SETORES VARRIÇÃO'!$H:$H,0)), IFERROR( INDEX(#REF!,MATCH($E10,#REF!,0)), INDEX(#REF!,MATCH($E10,#REF!,0)) ))) -> MG | D10: =IFERROR( INDEX(#REF!,MATCH($E10,#REF!,0)), IFERROR( INDEX('SETORES VARRIÇÃO'!$B:$B,MATCH($E10,'SETORES VARRIÇÃO'!$H:$H,0)), IFERROR( INDEX(#REF!,MATCH($E10,#REF!,0)), INDEX(#REF!,MATCH($E10,#REF!,0)) ))) -> MG10101VJ0012 | E10: =SUBSTITUTE(B10,"SMSUB-LUTOCAR-","") -> 03-0017 | F10: =IFERROR( INDEX(#REF!,MATCH($E10,#REF!,0)), IFERROR( INDEX('SETORES VARRIÇÃO'!$F:$F,MATCH($E10,'SETORES VARRIÇÃO'!$H:$H,0)), IFERROR( INDEX(#REF!,MATCH($E10,#REF!,0)), INDEX(#REF!,MATCH($E10,#REF!,0)) ))) -> Segunda a Domingo | G10: OFF | H10: 100% (Bateria desatualizada) | I10: 05/12/2025 12:36:48
A11: 46009 | B11: SMSUB-LUTOCAR-03-0020 | C11: =IFERROR( INDEX(#REF!,MATCH($E11,#REF!,0)), IFERROR( INDEX('SETORES VARRIÇÃO'!$A:$A,MATCH($E11,'SETORES VARRIÇÃO'!$H:$H,0)), IFERROR( INDEX(#REF!,MATCH($E11,#REF!,0)), INDEX(#REF!,MATCH($E11,#REF!,0)) ))) -> CV | D11: =IFERROR( INDEX(#REF!,MATCH($E11,#REF!,0)), IFERROR( INDEX('SETORES VARRIÇÃO'!$B:$B,MATCH($E11,'SETORES VARRIÇÃO'!$H:$H,0)), IFERROR( INDEX(#REF!,MATCH($E11,#REF!,0)), INDEX(#REF!,MATCH($E11,#REF!,0)) ))) -> CV10304VJ0026 | E11: =SUBSTITUTE(B11,"SMSUB-LUTOCAR-","") -> 03-0020 | F11: =IFERROR( INDEX(#REF!,MATCH($E11,#REF!,0)), IFERROR( INDEX('SETORES VARRIÇÃO'!$F:$F,MATCH($E11,'SETORES VARRIÇÃO'!$H:$H,0)), IFERROR( INDEX(#REF!,MATCH($E11,#REF!,0)), INDEX(#REF!,MATCH($E11,#REF!,0)) ))) -> Quarta/Sábado | G11: OFF | H11: 100% (Bateria desatualizada) | I11: 02/12/2025 20:56:48
A12: 46009 | B12: SMSUB-LUTOCAR-03-0022 | C12: =IFERROR( INDEX(#REF!,MATCH($E12,#REF!,0)), IFERROR( INDEX('SETORES VARRIÇÃO'!$A:$A,MATCH($E12,'SETORES VARRIÇÃO'!$H:$H,0)), IFERROR( INDEX(#REF!,MATCH($E12,#REF!,0)), INDEX(#REF!,MATCH($E12,#REF!,0)) ))) -> CV | D12: =IFERROR( INDEX(#REF!,MATCH($E12,#REF!,0)), IFERROR( INDEX('SETORES VARRIÇÃO'!$B:$B,MATCH($E12,'SETORES VARRIÇÃO'!$H:$H,0)), IFERROR( INDEX(#REF!,MATCH($E12,#REF!,0)), INDEX(#REF!,MATCH($E12,#REF!,0)) ))) -> CV10203VJ0056 | E12: =SUBSTITUTE(B12,"SMSUB-LUTOCAR-","") -> 03-0022 | F12: =IFERROR( INDEX(#REF!,MATCH($E12,#REF!,0)), IFERROR( INDEX('SETORES VARRIÇÃO'!$F:$F,MATCH($E12,'SETORES VARRIÇÃO'!$H:$H,0)), IFERROR( INDEX(#REF!,MATCH($E12,#REF!,0)), INDEX(#REF!,MATCH($E12,#REF!,0)) ))) -> Terça/Quinta/Sábado | G12: OFF | H12: 100% (Bateria desatualizada) | I12: 11/12/2025 01:57:42
A13: 46009 | B13: SMSUB-LUTOCAR-03-0026 | C13: =IFERROR( INDEX(#REF!,MATCH($E13,#REF!,0)), IFERROR( INDEX('SETORES VARRIÇÃO'!$A:$A,MATCH($E13,'SETORES VARRIÇÃO'!$H:$H,0)), IFERROR( INDEX(#REF!,MATCH($E13,#REF!,0)), INDEX(#REF!,MATCH($E13,#REF!,0)) ))) -> JT | D13: =IFERROR( INDEX(#REF!,MATCH($E13,#REF!,0)), IFERROR( INDEX('SETORES VARRIÇÃO'!$B:$B,MATCH($E13,'SETORES VARRIÇÃO'!$H:$H,0)), IFERROR( INDEX(#REF!,MATCH($E13,#REF!,0)), INDEX(#REF!,MATCH($E13,#REF!,0)) ))) -> JT10101VL0001 | E13: =SUBSTITUTE(B13,"SMSUB-LUTOCAR-","") -> 03-0026 | F13: =IFERROR( INDEX(#REF!,MATCH($E13,#REF!,0)), IFERROR( INDEX('SETORES VARRIÇÃO'!$F:$F,MATCH($E13,'SETORES VARRIÇÃO'!$H:$H,0)), IFERROR( INDEX(#REF!,MATCH($E13,#REF!,0)), INDEX(#REF!,MATCH($E13,#REF!,0)) ))) -> Segunda a Domingo | G13: OFF | H13: 100% (Bateria desatualizada) | I13: 05/12/2025 21:25:16
... A97: 46052 | B97: SMSUB-LUTOCAR-03-0025 | C97: =IFERROR( INDEX(#REF!,MATCH($E97,#REF!,0)), IFERROR( INDEX('SETORES VARRIÇÃO'!$A:$A,MATCH($E97,'SETORES VARRIÇÃO'!$H:$H,0)), IFERROR( INDEX(#REF!,MATCH($E97,#REF!,0)), INDEX(#REF!,MATCH($E97,#REF!,0)) ))) -> JT | D97: =IFERROR( INDEX(#REF!,MATCH($E97,#REF!,0)), IFERROR( INDEX('SETORES VARRIÇÃO'!$B:$B,MATCH($E97,'SETORES VARRIÇÃO'!$H:$H,0)), IFERROR( INDEX(#REF!,MATCH($E97,#REF!,0)), INDEX(#REF!,MATCH($E97,#REF!,0)) ))) -> JT10304VJ0043 | E97: =SUBSTITUTE(B97,"SMSUB-LUTOCAR-","") -> 03-0025 | F97: =IFERROR( INDEX(#REF!,MATCH($E97,#REF!,0)), IFERROR( INDEX('SETORES VARRIÇÃO'!$F:$F,MATCH($E97,'SETORES VARRIÇÃO'!$H:$H,0)), IFERROR( INDEX(#REF!,MATCH($E97,#REF!,0)), INDEX(#REF!,MATCH($E97,#REF!,0)) ))) -> Quarta/Sábado | G97: OFF | H97: 64% (Bateria desatualizada) | I97: 28/01/2026 10:44:34
A98: 46052 | B98: SMSUB-LUTOCAR-03-0001 | C98: =IFERROR( INDEX(#REF!,MATCH($E98,#REF!,0)), IFERROR( INDEX('SETORES VARRIÇÃO'!$A:$A,MATCH($E98,'SETORES VARRIÇÃO'!$H:$H,0)), IFERROR( INDEX(#REF!,MATCH($E98,#REF!,0)), INDEX(#REF!,MATCH($E98,#REF!,0)) ))) -> JT | D98: =IFERROR( INDEX(#REF!,MATCH($E98,#REF!,0)), IFERROR( INDEX('SETORES VARRIÇÃO'!$B:$B,MATCH($E98,'SETORES VARRIÇÃO'!$H:$H,0)), IFERROR( INDEX(#REF!,MATCH($E98,#REF!,0)), INDEX(#REF!,MATCH($E98,#REF!,0)) ))) -> JT10303VJ0035 | E98: =SUBSTITUTE(B98,"SMSUB-LUTOCAR-","") -> 03-0001 | F98: =IFERROR( INDEX(#REF!,MATCH($E98,#REF!,0)), IFERROR( INDEX('SETORES VARRIÇÃO'!$F:$F,MATCH($E98,'SETORES VARRIÇÃO'!$H:$H,0)), IFERROR( INDEX(#REF!,MATCH($E98,#REF!,0)), INDEX(#REF!,MATCH($E98,#REF!,0)) ))) -> Terça/Sexta | G98: OFF | H98: 0.74 | I98: 30/01/2026 09:42:46
A99: 46052 | B99: SMSUB-LUTOCAR-03-0002 | C99: =IFERROR( INDEX(#REF!,MATCH($E99,#REF!,0)), IFERROR( INDEX('SETORES VARRIÇÃO'!$A:$A,MATCH($E99,'SETORES VARRIÇÃO'!$H:$H,0)), IFERROR( INDEX(#REF!,MATCH($E99,#REF!,0)), INDEX(#REF!,MATCH($E99,#REF!,0)) ))) -> JT | D99: =IFERROR( INDEX(#REF!,MATCH($E99,#REF!,0)), IFERROR( INDEX('SETORES VARRIÇÃO'!$B:$B,MATCH($E99,'SETORES VARRIÇÃO'!$H:$H,0)), IFERROR( INDEX(#REF!,MATCH($E99,#REF!,0)), INDEX(#REF!,MATCH($E99,#REF!,0)) ))) -> JT10303VJ0025 | E99: =SUBSTITUTE(B99,"SMSUB-LUTOCAR-","") -> 03-0002 | F99: =IFERROR( INDEX(#REF!,MATCH($E99,#REF!,0)), IFERROR( INDEX('SETORES VARRIÇÃO'!$F:$F,MATCH($E99,'SETORES VARRIÇÃO'!$H:$H,0)), IFERROR( INDEX(#REF!,MATCH($E99,#REF!,0)), INDEX(#REF!,MATCH($E99,#REF!,0)) ))) -> Terça/Sexta | G99: OFF | H99: 44% (Bateria desatualizada) | I99: 06/12/2025 17:00:15
A100: 46052 | B100: SMSUB-LUTOCAR-03-0003 | C100: =IFERROR( INDEX(#REF!,MATCH($E100,#REF!,0)), IFERROR( INDEX('SETORES VARRIÇÃO'!$A:$A,MATCH($E100,'SETORES VARRIÇÃO'!$H:$H,0)), IFERROR( INDEX(#REF!,MATCH($E100,#REF!,0)), INDEX(#REF!,MATCH($E100,#REF!,0)) ))) -> CV | D100: =IFERROR( INDEX(#REF!,MATCH($E100,#REF!,0)), IFERROR( INDEX('SETORES VARRIÇÃO'!$B:$B,MATCH($E100,'SETORES VARRIÇÃO'!$H:$H,0)), IFERROR( INDEX(#REF!,MATCH($E100,#REF!,0)), INDEX(#REF!,MATCH($E100,#REF!,0)) ))) -> CV10304VJ0025 | E100: =SUBSTITUTE(B100,"SMSUB-LUTOCAR-","") -> 03-0003 | F100: =IFERROR( INDEX(#REF!,MATCH($E100,#REF!,0)), IFERROR( INDEX('SETORES VARRIÇÃO'!$F:$F,MATCH($E100,'SETORES VARRIÇÃO'!$H:$H,0)), IFERROR( INDEX(#REF!,MATCH($E100,#REF!,0)), INDEX(#REF!,MATCH($E100,#REF!,0)) ))) -> Quarta/Sábado | G100: OFF | H100: 0.89 | I100: 30/01/2026 09:47:08
A101: 46052 | B101: SMSUB-LUTOCAR-03-0004 | C101: =IFERROR( INDEX(#REF!,MATCH($E101,#REF!,0)), IFERROR( INDEX('SETORES VARRIÇÃO'!$A:$A,MATCH($E101,'SETORES VARRIÇÃO'!$H:$H,0)), IFERROR( INDEX(#REF!,MATCH($E101,#REF!,0)), INDEX(#REF!,MATCH($E101,#REF!,0)) ))) -> JT | D101: =IFERROR( INDEX(#REF!,MATCH($E101,#REF!,0)), IFERROR( INDEX('SETORES VARRIÇÃO'!$B:$B,MATCH($E101,'SETORES VARRIÇÃO'!$H:$H,0)), IFERROR( INDEX(#REF!,MATCH($E101,#REF!,0)), INDEX(#REF!,MATCH($E101,#REF!,0)) ))) -> JT10304VJ0059 | E101: =SUBSTITUTE(B101,"SMSUB-LUTOCAR-","") -> 03-0004 | F101: =IFERROR( INDEX(#REF!,MATCH($E101,#REF!,0)), IFERROR( INDEX('SETORES VARRIÇÃO'!$F:$F,MATCH($E101,'SETORES VARRIÇÃO'!$H:$H,0)), IFERROR( INDEX(#REF!,MATCH($E101,#REF!,0)), INDEX(#REF!,MATCH($E101,#REF!,0)) ))) -> Quarta/Sábado | G101: OFF | H101: 64% (Bateria desatualizada) | I101: 28/01/2026 11:26:00
A102: 46052 | B102: SMSUB-LUTOCAR-03-0005 | C102: =IFERROR( INDEX(#REF!,MATCH($E102,#REF!,0)), IFERROR( INDEX('SETORES VARRIÇÃO'!$A:$A,MATCH($E102,'SETORES VARRIÇÃO'!$H:$H,0)), IFERROR( INDEX(#REF!,MATCH($E102,#REF!,0)), INDEX(#REF!,MATCH($E102,#REF!,0)) ))) -> JT | D102: =IFERROR( INDEX(#REF!,MATCH($E102,#REF!,0)), IFERROR( INDEX('SETORES VARRIÇÃO'!$B:$B,MATCH($E102,'SETORES VARRIÇÃO'!$H:$H,0)), IFERROR( INDEX(#REF!,MATCH($E102,#REF!,0)), INDEX(#REF!,MATCH($E102,#REF!,0)) ))) -> JT10202VJ0054 | E102: =SUBSTITUTE(B102,"SMSUB-LUTOCAR-","") -> 03-0005 | F102: =IFERROR( INDEX(#REF!,MATCH($E102,#REF!,0)), IFERROR( INDEX('SETORES VARRIÇÃO'!$F:$F,MATCH($E102,'SETORES VARRIÇÃO'!$H:$H,0)), IFERROR( INDEX(#REF!,MATCH($E102,#REF!,0)), INDEX(#REF!,MATCH($E102,#REF!,0)) ))) -> Segunda/Quarta/Sexta | G102: ON | H102: 0.73 | I102: 30/01/2026 09:47:49
A103: 46052 | B103: SMSUB-LUTOCAR-03-0006 | C103: =IFERROR( INDEX(#REF!,MATCH($E103,#REF!,0)), IFERROR( INDEX('SETORES VARRIÇÃO'!$A:$A,MATCH($E103,'SETORES VARRIÇÃO'!$H:$H,0)), IFERROR( INDEX(#REF!,MATCH($E103,#REF!,0)), INDEX(#REF!,MATCH($E103,#REF!,0)) ))) -> MG | D103: =IFERROR( INDEX(#REF!,MATCH($E103,#REF!,0)), IFERROR( INDEX('SETORES VARRIÇÃO'!$B:$B,MATCH($E103,'SETORES VARRIÇÃO'!$H:$H,0)), IFERROR( INDEX(#REF!,MATCH($E103,#REF!,0)), INDEX(#REF!,MATCH($E103,#REF!,0)) ))) -> MG10101VJ0006 | E103: =SUBSTITUTE(B103,"SMSUB-LUTOCAR-","") -> 03-0006 | F103: =IFERROR( INDEX(#REF!,MATCH($E103,#REF!,0)), IFERROR( INDEX('SETORES VARRIÇÃO'!$F:$F,MATCH($E103,'SETORES VARRIÇÃO'!$H:$H,0)), IFERROR( INDEX(#REF!,MATCH($E103,#REF!,0)), INDEX(#REF!,MATCH($E103,#REF!,0)) ))) -> Segunda a Domingo | G103: ON | H103: 0.34 | I103: 30/01/2026 09:46:04
A104: 46052 | B104: SMSUB-LUTOCAR-03-0007 | C104: =IFERROR( INDEX(#REF!,MATCH($E104,#REF!,0)), IFERROR( INDEX('SETORES VARRIÇÃO'!$A:$A,MATCH($E104,'SETORES VARRIÇÃO'!$H:$H,0)), IFERROR( INDEX(#REF!,MATCH($E104,#REF!,0)), INDEX(#REF!,MATCH($E104,#REF!,0)) ))) -> JT | D104: =IFERROR( INDEX(#REF!,MATCH($E104,#REF!,0)), IFERROR( INDEX('SETORES VARRIÇÃO'!$B:$B,MATCH($E104,'SETORES VARRIÇÃO'!$H:$H,0)), IFERROR( INDEX(#REF!,MATCH($E104,#REF!,0)), INDEX(#REF!,MATCH($E104,#REF!,0)) ))) -> JT10304VJ0048 | E104: =SUBSTITUTE(B104,"SMSUB-LUTOCAR-","") -> 03-0007 | F104: =IFERROR( INDEX(#REF!,MATCH($E104,#REF!,0)), IFERROR( INDEX('SETORES VARRIÇÃO'!$F:$F,MATCH($E104,'SETORES VARRIÇÃO'!$H:$H,0)), IFERROR( INDEX(#REF!,MATCH($E104,#REF!,0)), INDEX(#REF!,MATCH($E104,#REF!,0)) ))) -> Quarta/Sábado | G104: ON | H104: 0 | I104: 30/01/2026 09:30:53
A105: 46052 | B105: SMSUB-LUTOCAR-03-0008 | C105: =IFERROR( INDEX(#REF!,MATCH($E105,#REF!,0)), IFERROR( INDEX('SETORES VARRIÇÃO'!$A:$A,MATCH($E105,'SETORES VARRIÇÃO'!$H:$H,0)), IFERROR( INDEX(#REF!,MATCH($E105,#REF!,0)), INDEX(#REF!,MATCH($E105,#REF!,0)) ))) -> JT | D105: =IFERROR( INDEX(#REF!,MATCH($E105,#REF!,0)), IFERROR( INDEX('SETORES VARRIÇÃO'!$B:$B,MATCH($E105,'SETORES VARRIÇÃO'!$H:$H,0)), IFERROR( INDEX(#REF!,MATCH($E105,#REF!,0)), INDEX(#REF!,MATCH($E105,#REF!,0)) ))) -> JT10303VJ0036 | E105: =SUBSTITUTE(B105,"SMSUB-LUTOCAR-","") -> 03-0008 | F105: =IFERROR( INDEX(#REF!,MATCH($E105,#REF!,0)), IFERROR( INDEX('SETORES VARRIÇÃO'!$F:$F,MATCH($E105,'SETORES VARRIÇÃO'!$H:$H,0)), IFERROR( INDEX(#REF!,MATCH($E105,#REF!,0)), INDEX(#REF!,MATCH($E105,#REF!,0)) ))) -> Terça/Sexta | G105: ON | H105: 0.54 | I105: 30/01/2026 09:46:25
A106: 46052 | B106: SMSUB-LUTOCAR-03-0009 | C106: =IFERROR( INDEX(#REF!,MATCH($E106,#REF!,0)), IFERROR( INDEX('SETORES VARRIÇÃO'!$A:$A,MATCH($E106,'SETORES VARRIÇÃO'!$H:$H,0)), IFERROR( INDEX(#REF!,MATCH($E106,#REF!,0)), INDEX(#REF!,MATCH($E106,#REF!,0)) ))) -> MG | D106: =IFERROR( INDEX(#REF!,MATCH($E106,#REF!,0)), IFERROR( INDEX('SETORES VARRIÇÃO'!$B:$B,MATCH($E106,'SETORES VARRIÇÃO'!$H:$H,0)), IFERROR( INDEX(#REF!,MATCH($E106,#REF!,0)), INDEX(#REF!,MATCH($E106,#REF!,0)) ))) -> MG10101VJ0009 | E106: =SUBSTITUTE(B106,"SMSUB-LUTOCAR-","") -> 03-0009 | F106: =IFERROR( INDEX(#REF!,MATCH($E106,#REF!,0)), IFERROR( INDEX('SETORES VARRIÇÃO'!$F:$F,MATCH($E106,'SETORES VARRIÇÃO'!$H:$H,0)), IFERROR( INDEX(#REF!,MATCH($E106,#REF!,0)), INDEX(#REF!,MATCH($E106,#REF!,0)) ))) -> Segunda a Domingo | G106: ON | H106: 0.54 | I106: 30/01/2026 07:40:03
A107: 46052 | B107: SMSUB-LUTOCAR-03-0010 | C107: =IFERROR( INDEX(#REF!,MATCH($E107,#REF!,0)), IFERROR( INDEX('SETORES VARRIÇÃO'!$A:$A,MATCH($E107,'SETORES VARRIÇÃO'!$H:$H,0)), IFERROR( INDEX(#REF!,MATCH($E107,#REF!,0)), INDEX(#REF!,MATCH($E107,#REF!,0)) ))) -> CV | D107: =IFERROR( INDEX(#REF!,MATCH($E107,#REF!,0)), IFERROR( INDEX('SETORES VARRIÇÃO'!$B:$B,MATCH($E107,'SETORES VARRIÇÃO'!$H:$H,0)), IFERROR( INDEX(#REF!,MATCH($E107,#REF!,0)), INDEX(#REF!,MATCH($E107,#REF!,0)) ))) -> CV10304VJ0027 | E107: =SUBSTITUTE(B107,"SMSUB-LUTOCAR-","") -> 03-0010 | F107: =IFERROR( INDEX(#REF!,MATCH($E107,#REF!,0)), IFERROR( INDEX('SETORES VARRIÇÃO'!$F:$F,MATCH($E107,'SETORES VARRIÇÃO'!$H:$H,0)), IFERROR( INDEX(#REF!,MATCH($E107,#REF!,0)), INDEX(#REF!,MATCH($E107,#REF!,0)) ))) -> Quarta/Sábado | G107: ON | H107: 0.94 | I107: 29/01/2026 11:46:50
A108: 46052 | B108: SMSUB-LUTOCAR-03-0011 | C108: =IFERROR( INDEX(#REF!,MATCH($E108,#REF!,0)), IFERROR( INDEX('SETORES VARRIÇÃO'!$A:$A,MATCH($E108,'SETORES VARRIÇÃO'!$H:$H,0)), IFERROR( INDEX(#REF!,MATCH($E108,#REF!,0)), INDEX(#REF!,MATCH($E108,#REF!,0)) ))) -> CV | D108: =IFERROR( INDEX(#REF!,MATCH($E108,#REF!,0)), IFERROR( INDEX('SETORES VARRIÇÃO'!$B:$B,MATCH($E108,'SETORES VARRIÇÃO'!$H:$H,0)), IFERROR( INDEX(#REF!,MATCH($E108,#REF!,0)), INDEX(#REF!,MATCH($E108,#REF!,0)) ))) -> CV10203VJ0051 | E108: =SUBSTITUTE(B108,"SMSUB-LUTOCAR-","") -> 03-0011 | F108: =IFERROR( INDEX(#REF!,MATCH($E108,#REF!,0)), IFERROR( INDEX('SETORES VARRIÇÃO'!$F:$F,MATCH($E108,'SETORES VARRIÇÃO'!$H:$H,0)), IFERROR( INDEX(#REF!,MATCH($E108,#REF!,0)), INDEX(#REF!,MATCH($E108,#REF!,0)) ))) -> Terça/Quinta/Sábado | G108: ON | H108: 0.59 | I108: 30/01/2026 09:24:46
A109: 46052 | B109: SMSUB-LUTOCAR-03-0012 | C109: =IFERROR( INDEX(#REF!,MATCH($E109,#REF!,0)), IFERROR( INDEX('SETORES VARRIÇÃO'!$A:$A,MATCH($E109,'SETORES VARRIÇÃO'!$H:$H,0)), IFERROR( INDEX(#REF!,MATCH($E109,#REF!,0)), INDEX(#REF!,MATCH($E109,#REF!,0)) ))) -> CV | D109: =IFERROR( INDEX(#REF!,MATCH($E109,#REF!,0)), IFERROR( INDEX('SETORES VARRIÇÃO'!$B:$B,MATCH($E109,'SETORES VARRIÇÃO'!$H:$H,0)), IFERROR( INDEX(#REF!,MATCH($E109,#REF!,0)), INDEX(#REF!,MATCH($E109,#REF!,0)) ))) -> CV10203VJ0052 | E109: =SUBSTITUTE(B109,"SMSUB-LUTOCAR-","") -> 03-0012 | F109: =IFERROR( INDEX(#REF!,MATCH($E109,#REF!,0)), IFERROR( INDEX('SETORES VARRIÇÃO'!$F:$F,MATCH($E109,'SETORES VARRIÇÃO'!$H:$H,0)), IFERROR( INDEX(#REF!,MATCH($E109,#REF!,0)), INDEX(#REF!,MATCH($E109,#REF!,0)) ))) -> Terça/Quinta/Sábado | G109: ON | H109: 0.84 | I109: 30/01/2026 09:36:23
A110: 46052 | B110: SMSUB-LUTOCAR-03-0013 | C110: =IFERROR( INDEX(#REF!,MATCH($E110,#REF!,0)), IFERROR( INDEX('SETORES VARRIÇÃO'!$A:$A,MATCH($E110,'SETORES VARRIÇÃO'!$H:$H,0)), IFERROR( INDEX(#REF!,MATCH($E110,#REF!,0)), INDEX(#REF!,MATCH($E110,#REF!,0)) ))) -> MG | D110: =IFERROR( INDEX(#REF!,MATCH($E110,#REF!,0)), IFERROR( INDEX('SETORES VARRIÇÃO'!$B:$B,MATCH($E110,'SETORES VARRIÇÃO'!$H:$H,0)), IFERROR( INDEX(#REF!,MATCH($E110,#REF!,0)), INDEX(#REF!,MATCH($E110,#REF!,0)) ))) -> MG10101VJ0013 | E110: =SUBSTITUTE(B110,"SMSUB-LUTOCAR-","") -> 03-0013 | F110: =IFERROR( INDEX(#REF!,MATCH($E110,#REF!,0)), IFERROR( INDEX('SETORES VARRIÇÃO'!$F:$F,MATCH($E110,'SETORES VARRIÇÃO'!$H:$H,0)), IFERROR( INDEX(#REF!,MATCH($E110,#REF!,0)), INDEX(#REF!,MATCH($E110,#REF!,0)) ))) -> Segunda a Domingo | G110: ON | H110: 0.54 | I110: 30/01/2026 09:47:27
A111: 46052 | B111: SMSUB-LUTOCAR-03-0014 | C111: =IFERROR( INDEX(#REF!,MATCH($E111,#REF!,0)), IFERROR( INDEX('SETORES VARRIÇÃO'!$A:$A,MATCH($E111,'SETORES VARRIÇÃO'!$H:$H,0)), IFERROR( INDEX(#REF!,MATCH($E111,#REF!,0)), INDEX(#REF!,MATCH($E111,#REF!,0)) ))) -> JT | D111: =IFERROR( INDEX(#REF!,MATCH($E111,#REF!,0)), IFERROR( INDEX('SETORES VARRIÇÃO'!$B:$B,MATCH($E111,'SETORES VARRIÇÃO'!$H:$H,0)), IFERROR( INDEX(#REF!,MATCH($E111,#REF!,0)), INDEX(#REF!,MATCH($E111,#REF!,0)) ))) -> JT10302VJ0011 | E111: =SUBSTITUTE(B111,"SMSUB-LUTOCAR-","") -> 03-0014 | F111: =IFERROR( INDEX(#REF!,MATCH($E111,#REF!,0)), IFERROR( INDEX('SETORES VARRIÇÃO'!$F:$F,MATCH($E111,'SETORES VARRIÇÃO'!$H:$H,0)), IFERROR( INDEX(#REF!,MATCH($E111,#REF!,0)), INDEX(#REF!,MATCH($E111,#REF!,0)) ))) -> Segunda/Quinta | G111: ON | H111: 0.67 | I111: 30/01/2026 09:33:09
A112: 46052 | B112: SMSUB-LUTOCAR-03-0015 | C112: =IFERROR( INDEX(#REF!,MATCH($E112,#REF!,0)), IFERROR( INDEX('SETORES VARRIÇÃO'!$A:$A,MATCH($E112,'SETORES VARRIÇÃO'!$H:$H,0)), IFERROR( INDEX(#REF!,MATCH($E112,#REF!,0)), INDEX(#REF!,MATCH($E112,#REF!,0)) ))) -> CV | D112: =IFERROR( INDEX(#REF!,MATCH($E112,#REF!,0)), IFERROR( INDEX('SETORES VARRIÇÃO'!$B:$B,MATCH($E112,'SETORES VARRIÇÃO'!$H:$H,0)), IFERROR( INDEX(#REF!,MATCH($E112,#REF!,0)), INDEX(#REF!,MATCH($E112,#REF!,0)) ))) -> CV10203VJ0057 | E112: =SUBSTITUTE(B112,"SMSUB-LUTOCAR-","") -> 03-0015 | F112: =IFERROR( INDEX(#REF!,MATCH($E112,#REF!,0)), IFERROR( INDEX('SETORES VARRIÇÃO'!$F:$F,MATCH($E112,'SETORES VARRIÇÃO'!$H:$H,0)), IFERROR( INDEX(#REF!,MATCH($E112,#REF!,0)), INDEX(#REF!,MATCH($E112,#REF!,0)) ))) -> Terça/Quinta/Sábado | G112: ON | H112: 0.78 | I112: 30/01/2026 09:35:46
A113: 46052 | B113: SMSUB-LUTOCAR-03-0016 | C113: =IFERROR( INDEX(#REF!,MATCH($E113,#REF!,0)), IFERROR( INDEX('SETORES VARRIÇÃO'!$A:$A,MATCH($E113,'SETORES VARRIÇÃO'!$H:$H,0)), IFERROR( INDEX(#REF!,MATCH($E113,#REF!,0)), INDEX(#REF!,MATCH($E113,#REF!,0)) ))) -> JT | D113: =IFERROR( INDEX(#REF!,MATCH($E113,#REF!,0)), IFERROR( INDEX('SETORES VARRIÇÃO'!$B:$B,MATCH($E113,'SETORES VARRIÇÃO'!$H:$H,0)), IFERROR( INDEX(#REF!,MATCH($E113,#REF!,0)), INDEX(#REF!,MATCH($E113,#REF!,0)) ))) -> JT10304VJ0050 | E113: =SUBSTITUTE(B113,"SMSUB-LUTOCAR-","") -> 03-0016 | F113: =IFERROR( INDEX(#REF!,MATCH($E113,#REF!,0)), IFERROR( INDEX('SETORES VARRIÇÃO'!$F:$F,MATCH($E113,'SETORES VARRIÇÃO'!$H:$H,0)), IFERROR( INDEX(#REF!,MATCH($E113,#REF!,0)), INDEX(#REF!,MATCH($E113,#REF!,0)) ))) -> Quarta/Sábado | G113: ON | H113: 0.65 | I113: 30/01/2026 09:32:38
... A116: 46052 | B116: SMSUB-LUTOCAR-03-0019 | C116: =IFERROR( INDEX(#REF!,MATCH($E116,#REF!,0)), IFERROR( INDEX('SETORES VARRIÇÃO'!$A:$A,MATCH($E116,'SETORES VARRIÇÃO'!$H:$H,0)), IFERROR( INDEX(#REF!,MATCH($E116,#REF!,0)), INDEX(#REF!,MATCH($E116,#REF!,0)) ))) -> JT | D116: =IFERROR( INDEX(#REF!,MATCH($E116,#REF!,0)), IFERROR( INDEX('SETORES VARRIÇÃO'!$B:$B,MATCH($E116,'SETORES VARRIÇÃO'!$H:$H,0)), IFERROR( INDEX(#REF!,MATCH($E116,#REF!,0)), INDEX(#REF!,MATCH($E116,#REF!,0)) ))) -> JT10304VJ0049 | E116: =SUBSTITUTE(B116,"SMSUB-LUTOCAR-","") -> 03-0019 | F116: =IFERROR( INDEX(#REF!,MATCH($E116,#REF!,0)), IFERROR( INDEX('SETORES VARRIÇÃO'!$F:$F,MATCH($E116,'SETORES VARRIÇÃO'!$H:$H,0)), IFERROR( INDEX(#REF!,MATCH($E116,#REF!,0)), INDEX(#REF!,MATCH($E116,#REF!,0)) ))) -> Quarta/Sábado | G116: ON | H116: 0.8 | I116: 30/01/2026 09:39:01
A117: 46052 | B117: SMSUB-LUTOCAR-03-0020 | C117: =IFERROR( INDEX(#REF!,MATCH($E117,#REF!,0)), IFERROR( INDEX('SETORES VARRIÇÃO'!$A:$A,MATCH($E117,'SETORES VARRIÇÃO'!$H:$H,0)), IFERROR( INDEX(#REF!,MATCH($E117,#REF!,0)), INDEX(#REF!,MATCH($E117,#REF!,0)) ))) -> CV | D117: =IFERROR( INDEX(#REF!,MATCH($E117,#REF!,0)), IFERROR( INDEX('SETORES VARRIÇÃO'!$B:$B,MATCH($E117,'SETORES VARRIÇÃO'!$H:$H,0)), IFERROR( INDEX(#REF!,MATCH($E117,#REF!,0)), INDEX(#REF!,MATCH($E117,#REF!,0)) ))) -> CV10304VJ0026 | E117: =SUBSTITUTE(B117,"SMSUB-LUTOCAR-","") -> 03-0020 | F117: =IFERROR( INDEX(#REF!,MATCH($E117,#REF!,0)), IFERROR( INDEX('SETORES VARRIÇÃO'!$F:$F,MATCH($E117,'SETORES VARRIÇÃO'!$H:$H,0)), IFERROR( INDEX(#REF!,MATCH($E117,#REF!,0)), INDEX(#REF!,MATCH($E117,#REF!,0)) ))) -> Quarta/Sábado | G117: OFF | H117: 79% (Bateria desatualizada) | I117: 28/01/2026 12:17:29
A118: 46052 | B118: SMSUB-LUTOCAR-03-0021 | C118: =IFERROR( INDEX(#REF!,MATCH($E118,#REF!,0)), IFERROR( INDEX('SETORES VARRIÇÃO'!$A:$A,MATCH($E118,'SETORES VARRIÇÃO'!$H:$H,0)), IFERROR( INDEX(#REF!,MATCH($E118,#REF!,0)), INDEX(#REF!,MATCH($E118,#REF!,0)) ))) -> MG | D118: =IFERROR( INDEX(#REF!,MATCH($E118,#REF!,0)), IFERROR( INDEX('SETORES VARRIÇÃO'!$B:$B,MATCH($E118,'SETORES VARRIÇÃO'!$H:$H,0)), IFERROR( INDEX(#REF!,MATCH($E118,#REF!,0)), INDEX(#REF!,MATCH($E118,#REF!,0)) ))) -> MG10101VJ0008 | E118: =SUBSTITUTE(B118,"SMSUB-LUTOCAR-","") -> 03-0021 | F118: =IFERROR( INDEX(#REF!,MATCH($E118,#REF!,0)), IFERROR( INDEX('SETORES VARRIÇÃO'!$F:$F,MATCH($E118,'SETORES VARRIÇÃO'!$H:$H,0)), IFERROR( INDEX(#REF!,MATCH($E118,#REF!,0)), INDEX(#REF!,MATCH($E118,#REF!,0)) ))) -> Segunda a Domingo | G118: ON | H118: 0.49 | I118: 30/01/2026 09:47:47
A119: 46052 | B119: SMSUB-LUTOCAR-03-0022 | C119: =IFERROR( INDEX(#REF!,MATCH($E119,#REF!,0)), IFERROR( INDEX('SETORES VARRIÇÃO'!$A:$A,MATCH($E119,'SETORES VARRIÇÃO'!$H:$H,0)), IFERROR( INDEX(#REF!,MATCH($E119,#REF!,0)), INDEX(#REF!,MATCH($E119,#REF!,0)) ))) -> CV | D119: =IFERROR( INDEX(#REF!,MATCH($E119,#REF!,0)), IFERROR( INDEX('SETORES VARRIÇÃO'!$B:$B,MATCH($E119,'SETORES VARRIÇÃO'!$H:$H,0)), IFERROR( INDEX(#REF!,MATCH($E119,#REF!,0)), INDEX(#REF!,MATCH($E119,#REF!,0)) ))) -> CV10203VJ0056 | E119: =SUBSTITUTE(B119,"SMSUB-LUTOCAR-","") -> 03-0022 | F119: =IFERROR( INDEX(#REF!,MATCH($E119,#REF!,0)), IFERROR( INDEX('SETORES VARRIÇÃO'!$F:$F,MATCH($E119,'SETORES VARRIÇÃO'!$H:$H,0)), IFERROR( INDEX(#REF!,MATCH($E119,#REF!,0)), INDEX(#REF!,MATCH($E119,#REF!,0)) ))) -> Terça/Quinta/Sábado | G119: ON | H119: 0.39 | I119: 29/01/2026 12:46:00
A120: 46052 | B120: SMSUB-LUTOCAR-03-0023 | C120: =IFERROR( INDEX(#REF!,MATCH($E120,#REF!,0)), IFERROR( INDEX('SETORES VARRIÇÃO'!$A:$A,MATCH($E120,'SETORES VARRIÇÃO'!$H:$H,0)), IFERROR( INDEX(#REF!,MATCH($E120,#REF!,0)), INDEX(#REF!,MATCH($E120,#REF!,0)) ))) -> JT | D120: =IFERROR( INDEX(#REF!,MATCH($E120,#REF!,0)), IFERROR( INDEX('SETORES VARRIÇÃO'!$B:$B,MATCH($E120,'SETORES VARRIÇÃO'!$H:$H,0)), IFERROR( INDEX(#REF!,MATCH($E120,#REF!,0)), INDEX(#REF!,MATCH($E120,#REF!,0)) ))) -> JT10102VJ0003 | E120: =SUBSTITUTE(B120,"SMSUB-LUTOCAR-","") -> 03-0023 | F120: =IFERROR( INDEX(#REF!,MATCH($E120,#REF!,0)), IFERROR( INDEX('SETORES VARRIÇÃO'!$F:$F,MATCH($E120,'SETORES VARRIÇÃO'!$H:$H,0)), IFERROR( INDEX(#REF!,MATCH($E120,#REF!,0)), INDEX(#REF!,MATCH($E120,#REF!,0)) ))) -> Segunda a Domingo | G120: ON | H120: 0.36 | I120: 30/01/2026 09:39:35
A121: 46052 | B121: SMSUB-LUTOCAR-03-0024 | C121: =IFERROR( INDEX(#REF!,MATCH($E121,#REF!,0)), IFERROR( INDEX('SETORES VARRIÇÃO'!$A:$A,MATCH($E121,'SETORES VARRIÇÃO'!$H:$H,0)), IFERROR( INDEX(#REF!,MATCH($E121,#REF!,0)), INDEX(#REF!,MATCH($E121,#REF!,0)) ))) -> JT | D121: =IFERROR( INDEX(#REF!,MATCH($E121,#REF!,0)), IFERROR( INDEX('SETORES VARRIÇÃO'!$B:$B,MATCH($E121,'SETORES VARRIÇÃO'!$H:$H,0)), IFERROR( INDEX(#REF!,MATCH($E121,#REF!,0)), INDEX(#REF!,MATCH($E121,#REF!,0)) ))) -> JT10304VJ0046 | E121: =SUBSTITUTE(B121,"SMSUB-LUTOCAR-","") -> 03-0024 | F121: =IFERROR( INDEX(#REF!,MATCH($E121,#REF!,0)), IFERROR( INDEX('SETORES VARRIÇÃO'!$F:$F,MATCH($E121,'SETORES VARRIÇÃO'!$H:$H,0)), IFERROR( INDEX(#REF!,MATCH($E121,#REF!,0)), INDEX(#REF!,MATCH($E121,#REF!,0)) ))) -> Quarta/Sábado | G121: ON | H121: 0.64 | I121: 30/01/2026 09:37:25
A122: 46052 | B122: SMSUB-LUTOCAR-03-0026 | C122: =IFERROR( INDEX(#REF!,MATCH($E122,#REF!,0)), IFERROR( INDEX('SETORES VARRIÇÃO'!$A:$A,MATCH($E122,'SETORES VARRIÇÃO'!$H:$H,0)), IFERROR( INDEX(#REF!,MATCH($E122,#REF!,0)), INDEX(#REF!,MATCH($E122,#REF!,0)) ))) -> JT | D122: =IFERROR( INDEX(#REF!,MATCH($E122,#REF!,0)), IFERROR( INDEX('SETORES VARRIÇÃO'!$B:$B,MATCH($E122,'SETORES VARRIÇÃO'!$H:$H,0)), IFERROR( INDEX(#REF!,MATCH($E122,#REF!,0)), INDEX(#REF!,MATCH($E122,#REF!,0)) ))) -> JT10101VL0001 | E122: =SUBSTITUTE(B122,"SMSUB-LUTOCAR-","") -> 03-0026 | F122: =IFERROR( INDEX(#REF!,MATCH($E122,#REF!,0)), IFERROR( INDEX('SETORES VARRIÇÃO'!$F:$F,MATCH($E122,'SETORES VARRIÇÃO'!$H:$H,0)), IFERROR( INDEX(#REF!,MATCH($E122,#REF!,0)), INDEX(#REF!,MATCH($E122,#REF!,0)) ))) -> Segunda a Domingo | G122: ON | H122: 0.59 | I122: 30/01/2026 09:47:27
A123: 46052 | B123: SMSUB-LUTOCAR-03-0027 | C123: =IFERROR( INDEX(#REF!,MATCH($E123,#REF!,0)), IFERROR( INDEX('SETORES VARRIÇÃO'!$A:$A,MATCH($E123,'SETORES VARRIÇÃO'!$H:$H,0)), IFERROR( INDEX(#REF!,MATCH($E123,#REF!,0)), INDEX(#REF!,MATCH($E123,#REF!,0)) ))) -> JT | D123: =IFERROR( INDEX(#REF!,MATCH($E123,#REF!,0)), IFERROR( INDEX('SETORES VARRIÇÃO'!$B:$B,MATCH($E123,'SETORES VARRIÇÃO'!$H:$H,0)), IFERROR( INDEX(#REF!,MATCH($E123,#REF!,0)), INDEX(#REF!,MATCH($E123,#REF!,0)) ))) -> JT10304VJ0052 | E123: =SUBSTITUTE(B123,"SMSUB-LUTOCAR-","") -> 03-0027 | F123: =IFERROR( INDEX(#REF!,MATCH($E123,#REF!,0)), IFERROR( INDEX('SETORES VARRIÇÃO'!$F:$F,MATCH($E123,'SETORES VARRIÇÃO'!$H:$H,0)), IFERROR( INDEX(#REF!,MATCH($E123,#REF!,0)), INDEX(#REF!,MATCH($E123,#REF!,0)) ))) -> Quarta/Sábado | G123: OFF | H123: 83% (Bateria desatualizada) | I123: 28/01/2026 11:44:28
A124: 46052 | B124: SMSUB-LUTOCAR-03-0028 | C124: =IFERROR( INDEX(#REF!,MATCH($E124,#REF!,0)), IFERROR( INDEX('SETORES VARRIÇÃO'!$A:$A,MATCH($E124,'SETORES VARRIÇÃO'!$H:$H,0)), IFERROR( INDEX(#REF!,MATCH($E124,#REF!,0)), INDEX(#REF!,MATCH($E124,#REF!,0)) ))) -> CV | D124: =IFERROR( INDEX(#REF!,MATCH($E124,#REF!,0)), IFERROR( INDEX('SETORES VARRIÇÃO'!$B:$B,MATCH($E124,'SETORES VARRIÇÃO'!$H:$H,0)), IFERROR( INDEX(#REF!,MATCH($E124,#REF!,0)), INDEX(#REF!,MATCH($E124,#REF!,0)) ))) -> CV10203VJ0058 | E124: =SUBSTITUTE(B124,"SMSUB-LUTOCAR-","") -> 03-0028 | F124: =IFERROR( INDEX(#REF!,MATCH($E124,#REF!,0)), IFERROR( INDEX('SETORES VARRIÇÃO'!$F:$F,MATCH($E124,'SETORES VARRIÇÃO'!$H:$H,0)), IFERROR( INDEX(#REF!,MATCH($E124,#REF!,0)), INDEX(#REF!,MATCH($E124,#REF!,0)) ))) -> Terça/Quinta/Sábado | G124: ON | H124: 0.74 | I124: 30/01/2026 09:33:14
A125: 46052 | B125: SMSUB-LUTOCAR-03-0029 | C125: =IFERROR( INDEX(#REF!,MATCH($E125,#REF!,0)), IFERROR( INDEX('SETORES VARRIÇÃO'!$A:$A,MATCH($E125,'SETORES VARRIÇÃO'!$H:$H,0)), IFERROR( INDEX(#REF!,MATCH($E125,#REF!,0)), INDEX(#REF!,MATCH($E125,#REF!,0)) ))) -> CV | D125: =IFERROR( INDEX(#REF!,MATCH($E125,#REF!,0)), IFERROR( INDEX('SETORES VARRIÇÃO'!$B:$B,MATCH($E125,'SETORES VARRIÇÃO'!$H:$H,0)), IFERROR( INDEX(#REF!,MATCH($E125,#REF!,0)), INDEX(#REF!,MATCH($E125,#REF!,0)) ))) -> CV10203VJ0055 | E125: =SUBSTITUTE(B125,"SMSUB-LUTOCAR-","") -> 03-0029 | F125: =IFERROR( INDEX(#REF!,MATCH($E125,#REF!,0)), IFERROR( INDEX('SETORES VARRIÇÃO'!$F:$F,MATCH($E125,'SETORES VARRIÇÃO'!$H:$H,0)), IFERROR( INDEX(#REF!,MATCH($E125,#REF!,0)), INDEX(#REF!,MATCH($E125,#REF!,0)) ))) -> Terça/Quinta/Sábado | G125: ON | H125: 0.54 | I125: 30/01/2026 09:28:17
...

Sheet TROCAS SELIMP
A1: DATA | B1: MOTIVO DA TROCA | C1: SETORES CV | D1: SETORES JT | E1: SETORES MG | F1: SETORES ST | G1: SINAL | H1: BATERIA | I1: STATUS
A2: 46009 | B2: CORRETIVA | D2: JT10203VJ0055 | G2: 46009 | I2: =IF(G2="","",IF(G2=A2,"ATUALIZADA","DESATUALIZADA")) -> ATUALIZADA
A3: 46010 | B3: CORRETIVA | E3: MG10101VJ0002 | G3: 46010 | I3: =IF(G3="","",IF(G3=A3,"ATUALIZADA","DESATUALIZADA")) -> ATUALIZADA
A4: 46010 | B4: CORRETIVA | E4: MG10101VJ0012 | G4: 46010 | I4: =IF(G4="","",IF(G4=A4,"ATUALIZADA","DESATUALIZADA")) -> ATUALIZADA
A5: 46010 | B5: CORRETIVA | E5: MG10101VJ0011 | G5: 46010 | I5: =IF(G5="","",IF(G5=A5,"ATUALIZADA","DESATUALIZADA")) -> ATUALIZADA
A6: 46010 | B6: CORRETIVA | E6: MG10101VJ0013 | G6: 46010 | I6: =IF(G6="","",IF(G6=A6,"ATUALIZADA","DESATUALIZADA")) -> ATUALIZADA
A7: 46010 | B7: CORRETIVA | E7: MG10101VJ0007 | G7: 46010 | I7: =IF(G7="","",IF(G7=A7,"ATUALIZADA","DESATUALIZADA")) -> ATUALIZADA
A8: 46010 | B8: CORRETIVA | E8: MG10101VJ0009 | G8: 46010 | I8: =IF(G8="","",IF(G8=A8,"ATUALIZADA","DESATUALIZADA")) -> ATUALIZADA
A9: 46010 | B9: CORRETIVA | E9: MG10101VJ0004 | G9: 46010 | I9: =IF(G9="","",IF(G9=A9,"ATUALIZADA","DESATUALIZADA")) -> ATUALIZADA
A10: 46011 | B10: CORRETIVA | C10: CV10203VJ0056 | G10: 46011 | I10: =IF(G10="","",IF(G10=A10,"ATUALIZADA","DESATUALIZADA")) -> ATUALIZADA
A11: 46011 | B11: CORRETIVA | C11: CV10203VJ0053 | G11: 46011 | I11: =IF(G11="","",IF(G11=A11,"ATUALIZADA","DESATUALIZADA")) -> ATUALIZADA
A12: 46011 | B12: CORRETIVA | C12: CV10203VJ0052 | G12: 46011 | I12: =IF(G12="","",IF(G12=A12,"ATUALIZADA","DESATUALIZADA")) -> ATUALIZADA
A13: 46011 | B13: CORRETIVA | C13: CV10304VJ0026 | G13: 45993 | I13: =IF(G13="","",IF(G13=A13,"ATUALIZADA","DESATUALIZADA")) -> DESATUALIZADA
A14: 46011 | B14: CORRETIVA | C14: CV10304VJ0023 | G14: 45994 | I14: =IF(G14="","",IF(G14=A14,"ATUALIZADA","DESATUALIZADA")) -> DESATUALIZADA
A15: 46013 | B15: CORRETIVA | C15: CV10202VJ0034 | G15: 46013 | I15: =IF(G15="","",IF(G15=A15,"ATUALIZADA","DESATUALIZADA")) -> ATUALIZADA
A16: 46013 | B16: CORRETIVA | C16: CV10202VJ0045 | G16: 46013 | I16: =IF(G16="","",IF(G16=A16,"ATUALIZADA","DESATUALIZADA")) -> ATUALIZADA
A17: 46013 | B17: CORRETIVA | C17: CV10202VJ0029 | G17: 46013 | I17: =IF(G17="","",IF(G17=A17,"ATUALIZADA","DESATUALIZADA")) -> ATUALIZADA
A18: 46013 | B18: CORRETIVA | C18: CV10202VJ0030 | G18: 46013 | I18: =IF(G18="","",IF(G18=A18,"ATUALIZADA","DESATUALIZADA")) -> ATUALIZADA
A19: 46013 | B19: CORRETIVA | C19: CV10202VJ0035 | G19: 46013 | I19: =IF(G19="","",IF(G19=A19,"ATUALIZADA","DESATUALIZADA")) -> ATUALIZADA
A20: 46013 | B20: CORRETIVA | C20: CV10202VJ0041 | G20: 46013 | I20: =IF(G20="","",IF(G20=A20,"ATUALIZADA","DESATUALIZADA")) -> ATUALIZADA
A21: 46014 | B21: CORRETIVA | C21: CV10202VJ0046 | G21: 46014 | I21: =IF(G21="","",IF(G21=A21,"ATUALIZADA","DESATUALIZADA")) -> ATUALIZADA
... A24: 46017 | B24: CORRETIVA | C24: CV10303VJ0022 | G24: 45998 | I24: =IF(G24="","",IF(G24=A24,"ATUALIZADA","DESATUALIZADA")) -> DESATUALIZADA
A25: 46018 | B25: CORRETIVA | D25: JT10304VJ0038 | G25: 46018 | I25: =IF(G25="","",IF(G25=A25,"ATUALIZADA","DESATUALIZADA")) -> ATUALIZADA
A26: 46018 | B26: CORRETIVA | D26: JT10304VJ0041 | G26: 46018 | I26: =IF(G26="","",IF(G26=A26,"ATUALIZADA","DESATUALIZADA")) -> ATUALIZADA
A27: 46021 | B27: CORRETIVA | D27: JT10303VJ0024 | G27: 46021 | I27: =IF(G27="","",IF(G27=A27,"ATUALIZADA","DESATUALIZADA")) -> ATUALIZADA
A28: 46021 | B28: CORRETIVA | D28: JT10303VJ0025 | G28: 45997 | I28: =IF(G28="","",IF(G28=A28,"ATUALIZADA","DESATUALIZADA")) -> DESATUALIZADA
A29: 46021 | B29: CORRETIVA | D29: JT10303VJ0026 | G29: 46021 | I29: =IF(G29="","",IF(G29=A29,"ATUALIZADA","DESATUALIZADA")) -> ATUALIZADA
A30: 46021 | B30: CORRETIVA | D30: JT10303VJ0029 | G30: 46021 | I30: =IF(G30="","",IF(G30=A30,"ATUALIZADA","DESATUALIZADA")) -> ATUALIZADA
A31: 46024 | B31: CORRETIVA | D31: JT10304VJ0036 | G31: 46024 | I31: =IF(G31="","",IF(G31=A31,"ATUALIZADA","DESATUALIZADA")) -> ATUALIZADA
A32: 46024 | B32: CORRETIVA | D32: JT10202VJ0056 | G32: 46024 | I32: =IF(G32="","",IF(G32=A32,"ATUALIZADA","DESATUALIZADA")) -> ATUALIZADA
A33: 46025 | B33: CORRETIVA | D33: JT10304VJ0059 | G33: 46025 | I33: =IF(G33="","",IF(G33=A33,"ATUALIZADA","DESATUALIZADA")) -> ATUALIZADA
A34: 46025 | B34: CORRETIVA | D34: JT10304VJ0047 | G34: 46025 | I34: =IF(G34="","",IF(G34=A34,"ATUALIZADA","DESATUALIZADA")) -> ATUALIZADA
A35: 46027 | B35: CORRETIVA | D35: JT10302VJ0005 | G35: 46027 | I35: =IF(G35="","",IF(G35=A35,"ATUALIZADA","DESATUALIZADA")) -> ATUALIZADA
A36: 46027 | B36: CORRETIVA | D36: JT10302VJ0011 | G36: 46027 | I36: =IF(G36="","",IF(G36=A36,"ATUALIZADA","DESATUALIZADA")) -> ATUALIZADA
A37: 46028 | B37: CORRETIVA | D37: JT10101VL0001 | G37: 46028 | I37: =IF(G37="","",IF(G37=A37,"ATUALIZADA","DESATUALIZADA")) -> ATUALIZADA
A38: 46028 | B38: CORRETIVA | E38: MG10101VJ0005 | G38: 46028 | I38: =IF(G38="","",IF(G38=A38,"ATUALIZADA","DESATUALIZADA")) -> ATUALIZADA
A39: 46028 | B39: CORRETIVA | E39: MG10101VJ0007 | G39: 46028 | I39: =IF(G39="","",IF(G39=A39,"ATUALIZADA","DESATUALIZADA")) -> ATUALIZADA
A40: 46028 | B40: CORRETIVA | E40: MG10101VJ0003 | G40: 46028 | I40: =IF(G40="","",IF(G40=A40,"ATUALIZADA","DESATUALIZADA")) -> ATUALIZADA
A41: 46030 | B41: CORRETIVA | D41: JT10302VJ0016 | G41: 46030 | I41: =IF(G41="","",IF(G41=A41,"ATUALIZADA","DESATUALIZADA")) -> ATUALIZADA
A42: 46030 | B42: CORRETIVA | D42: JT10302VJ0020 | G42: 46030 | I42: =IF(G42="","",IF(G42=A42,"ATUALIZADA","DESATUALIZADA")) -> ATUALIZADA
...

Sheet MANUTENÇÃO
A1: SUB | B1: SETOR | C1: STATUS ATUAL | D1: SELIMP | E1: EXECUÇÃO | F1: MOTIVO | G1: DATA COMUNICADO | H1: DATA MANUTENÇÃO | I1: ÚLTIMA COMUNICAÇÃO | J1: TROCAS APÓS PERCA | K1: TROCA 1 | L1: TROCA 2
A2: MG | B2: MG10101VJ0001 | C2: SINAL RECUPERADO | D2: 03-0124 | E2: Segunda a Domingo | F2: Bateria desatualizada após trocas | G2: 46063 | H2: 46077 | I2: 46043 | J2: =COUNT(K2:L2) -> 2 | K2: 46056 | L2: 46063
A3: JT | B3: JT20101VJ0003 | C3: SINAL RECUPERADO | D3: 03-0059 | E3: Segunda a Domingo | F3: Bateria desatualizada após trocas | G3: 46084 | H3: 46099 | I3: 46066 | J3: =COUNT(K3:L3) -> 2 | K3: 46076 | L3: 46083
A4: JT | B4: JT10303VJ0021 | C4: SINAL RECUPERADO | D4: 03-0137 | E4: Terça/Sexta | F4: Bateria desatualizada após trocas | G4: 46063 | H4: 46084 | I4: 46050 | J4: =COUNT(K4:L4) -> 2 | K4: 46056 | L4: 46063
A5: JT | B5: JT10303VJ0025 | C5: SINAL RECUPERADO | D5: 03-0002 | E5: Terça/Sexta | F5: Bateria desatualizada após trocas | G5: 46063 | H5: 46084 | I5: 45997 | J5: =COUNT(K5:L5) -> 2 | K5: 46045 | L5: 46056
A6: CV | B6: CV10203VJ0050 | C6: SINAL RECUPERADO | D6: 03-0071 | E6: Terça/Quinta/Sábado | F6: Bateria desatualizada após trocas | G6: 46063 | H6: 46084 | I6: 46004 | J6: =COUNT(K6:L6) -> 2 | K6: 46056 | L6: 46063
A7: CV | B7: CV10202VJ0032 | C7: SINAL RECUPERADO | D7: 03-0056 | E7: Segunda/Quarta/Sexta | F7: Bateria desatualizada após trocas | G7: 46084 | H7: 46099 | I7: 46055 | J7: =COUNT(K7:L7) -> 2 | K7: 46069 | L7: 46073
A8: CV | B8: CV10304VJ0024 | C8: SINAL RECUPERADO | D8: 03-0062 | E8: Quarta/Sábado | F8: Bateria desatualizada após trocas | G8: 46084 | H8: NÃO TEVE | I8: 46071 | J8: =COUNT(K8:L8) -> 2 | K8: 46074 | L8: 46083
A9: CV | B9: CV10304VJ0025 | C9: SINAL RECUPERADO | D9: 03-0003 | E9: Quarta/Sábado | F9: Sinal perdido e desatualizado para 2025 | G9: 46091 | H9: 46092 | I9: 45997 | J9: =COUNT(K9:L9) -> 0 | K9: NÃO TEVE | L9: NÃO TEVE
A10: JT | B10: JT10304VJ0048 | C10: SINAL RECUPERADO | D10: 03-0007 | E10: Quarta/Sábado | F10: Bateria travada no sistema | G10: ALINHADO POR LUCAS | H10: 46111 | I10: COMUNICAÇÃO OK | J10: =COUNT(K10:L10) -> 0 | K10: NÃO TEVE | L10: NÃO TEVE
A11: JT | B11: JT20101VJ0002 | C11: PENDENTE MANUTENÇÃO | D11: 03-0033 | E11: Segunda a Domingo | F11: Bateria desatualizada após trocas | G11: 46128 | I11: 46083 | J11: =COUNT(K11:L11) -> 2 | K11: 46092 | L11: 46099
A12: JT | B12: JT10303VJ0025 | C12: PENDENTE MANUTENÇÃO | D12: 03-0002 | E12: Terça/Sexta | F12: Bateria desatualizada após trocas | G12: 46128 | I12: 46097 | J12: =COUNT(K12:L12) -> 2 | K12: 46108 | L12: 46126
A13: JT | B13: JT10303VJ0021 | C13: EM ANÁLISE | D13: 03-0137 | E13: Terça/Sexta | J13: =COUNT(K13:L13) -> 1 | K13: 46119
A14: CV | B14: CV10303VJ0019 | C14: EM ANÁLISE | D14: 03-0061 | E14: Terça/Sexta | J14: =COUNT(K14:L14) -> 1 | K14: 46119
A15: MG | B15: MG10202VJ0031 | C15: EM ANÁLISE | D15: 03-0240 | E15: Segunda/Quarta/Sexta | J15: =COUNT(K15:L15) -> 1 | K15: 46122
A16: MG | B16: MG10202VJ0032 | C16: EM ANÁLISE | D16: 03-0233 | E16: Segunda/Quarta/Sexta | J16: =COUNT(K16:L16) -> 1 | K16: 46122
A17: MG | B17: MG10303VJ0019 | C17: EM ANÁLISE | D17: 03-0214 | E17: Terça/Sexta | J17: =COUNT(K17:L17) -> 1 | K17: 46122
A18: ST | B18: ST10101VJ0014 | C18: EM ANÁLISE | D18: 03-0196 | E18: Segunda a Domingo | J18: =COUNT(K18:L18) -> 1 | K18: 46122
A19: ST | B19: ST10101VJ0015 | C19: EM ANÁLISE | D19: 03-0244 | E19: Segunda a Domingo | J19: =COUNT(K19:L19) -> 1 | K19: 46122
A20: JT | B20: JT10303VJ0058 | C20: EM ANÁLISE | D20: 03-0111 | E20: Terça/Sexta | J20: =COUNT(K20:L20) -> 1 | K20: 46126
A21: ST | B21: ST10203VJ0080 | C21: EM ANÁLISE | D21: 03-0316 | E21: Terça/Quinta/Sábado | J21: =COUNT(K21:L21) -> 1 | K21: 46126
A22: CV | B22: CV10101VJ0006 | C22: EM ANÁLISE | D22: 03-0112 | E22: =VLOOKUP(B22,'SETORES VARRIÇÃO'!B:F,5,0) -> Segunda a Domingo | J22: =COUNT(K22:L22) -> 1 | K22: 46127
A23: CV | B23: CV10101VJ0007 | C23: EM ANÁLISE | D23: 03-0096 | E23: =VLOOKUP(B23,'SETORES VARRIÇÃO'!B:F,5,0) -> Segunda a Domingo | J23: =COUNT(K23:L23) -> 1 | K23: 46127
A24: MG | B24: MG10101VJ0009 | C24: EM ANÁLISE | D24: 03-0009 | E24: =VLOOKUP(B24,'SETORES VARRIÇÃO'!B:F,5,0) -> Segunda a Domingo | J24: =COUNT(K24:L24) -> 1 | K24: 46127
A25: MG | B25: MG10304VJ0022 | C25: EM ANÁLISE | D25: 03-0220 | E25: =VLOOKUP(B25,'SETORES VARRIÇÃO'!B:F,5,0) -> Quarta/Sábado | J25: =COUNT(K25:L25) -> 1 | K25: 46127
A26: ST | B26: ST10101VJ0004 | C26: EM ANÁLISE | D26: 03-0284 | E26: =VLOOKUP(B26,'SETORES VARRIÇÃO'!B:F,5,0) -> Segunda a Domingo | J26: =COUNT(K26:L26) -> 1 | K26: 46127
A27: MG | B27: MG10202VP0013/14 | C27: EM ANÁLISE | D27: 03-0157 | E27: Segunda/Quarta/Sexta | J27: =COUNT(K27:L27) -> 1 | K27: 46129
A28: MG | B28: MG10202VP0022/23 | C28: EM ANÁLISE | D28: 03-0164 | E28: Segunda/Quarta/Sexta | J28: =COUNT(K28:L28) -> 1 | K28: 46129
A29: MG | B29: MG10202VJ0042 | C29: EM ANÁLISE | D29: 03-0236 | E29: Segunda/Quarta/Sexta | J29: =COUNT(K29:L29) -> 1 | K29: 46129
A30: JT | B30: JT10302VJ0014 | C30: EM ANÁLISE | D30: 03-0110 | E30: Segunda/Quinta | J30: =COUNT(K30:L30) -> 1 | K30: 46132
A31: CV | B31: CV10101VP0004 | C31: EM ANÁLISE | D31: 03-0213 | E31: =VLOOKUP(B31,'SETORES PRAÇA'!B:F,5,0) -> Segunda a Sábado | J31: =COUNT(K31:L31) -> 1 | K31: 46127
A32: CV | B32: CV10101VP0005 | C32: EM ANÁLISE | D32: 03-0305 | E32: =VLOOKUP(B32,'SETORES PRAÇA'!B:F,5,0) -> Segunda a Sábado | J32: =COUNT(K32:L32) -> 1 | K32: 46127
A33: CV | B33: CV10202VP0011 | C33: EM ANÁLISE | D33: 03-0296 | E33: =VLOOKUP(B33,'SETORES PRAÇA'!B:F,5,0) -> Segunda/Quarta/Sexta | J33: =COUNT(K33:L33) -> 1 | K33: 46127
A34: MG | B34: MG10101VJ0005 | C34: EM ANÁLISE | D34: 03-0087 | E34: Segunda a Domingo | J34: =COUNT(K34:L34) -> 1 | K34: 46135
A35: MG | B35: MG10203VJ0047 | C35: EM ANÁLISE | D35: 03-0172 | E35: Terça/Quinta/Sábado | J35: =COUNT(K35:L35) -> 1 | K35: 46135
A36: ST | B36: ST10303VJ0047 | C36: EM ANÁLISE | D36: 03-0281 | E36: Terça/Sexta
A37: CV | B37: CV10203VJ0060 | C37: EM ANÁLISE | D37: 03-0099
A38: CV | B38: CV10203VJ0056 | C38: EM ANÁLISE | D38: 03-0022
A39: CV | B39: CV10202VJ0035 | C39: EM ANÁLISE | D39: 03-0097 | E39: Segunda/Quarta/Sexta
A40: CV | B40: CV10202VJ0044 | C40: EM ANÁLISE | D40: 03-0113 | E40: Segunda/Quarta/Sexta
...

Sheet SETORES VARRIÇÃO
A1: SUBPREFEITURA | B1: SETOR | C1: TURNO | D1: SERVIÇO | E1: FREQUÊNCIA | F1: DIAS DE EXECUÇÃO | G1: KM_PROD | H1: SELIMP | I1: INSTALAÇÃO | J1: LIMPEBRAS | K1: INSTALAÇÃO
A2: CV | B2: CV10101VL0001 | C2: Diurno | D2: VARRIÇÃO MANUAL DE VIAS E LOGRADOUROS PÚBLICOS - SARJETAS E CALÇADAS | E2: Diário | F2: Segunda a Domingo | G2: 5.430886 | H2: 03-0036 | I2: 45997 | J2: 017 | K2: 46017
A3: CV | B3: CV10101VL0002 | C3: Diurno | D3: VARRIÇÃO MANUAL DE VIAS E LOGRADOUROS PÚBLICOS - SARJETAS E CALÇADAS | E3: Diário | F3: Segunda a Domingo | G3: 5.354424 | H3: 03-0106 | I3: 45997 | J3: 198 | K3: 46017
A4: CV | B4: CV10101VJ0001 | C4: Diurno | D4: VARRIÇÃO MANUAL DE VIAS E LOGRADOUROS PÚBLICOS - SARJETAS | E4: Diário | F4: Segunda a Domingo | G4: 5.914789 | H4: 03-0055 | I4: 45994 | J4: 012 | K4: 46017
A5: CV | B5: CV10101VJ0002 | C5: Diurno | D5: VARRIÇÃO MANUAL DE VIAS E LOGRADOUROS PÚBLICOS - SARJETAS | E5: Diário | F5: Segunda a Domingo | G5: 5.877836 | H5: 03-0060 | I5: 45994 | J5: 018 | K5: 46017
A6: CV | B6: CV10101VJ0003 | C6: Diurno | D6: VARRIÇÃO MANUAL DE VIAS E LOGRADOUROS PÚBLICOS - SARJETAS | E6: Diário | F6: Segunda a Domingo | G6: 6.054219 | H6: 03-0064 | I6: 45995 | J6: 027 | K6: 46017
A7: CV | B7: CV10101VJ0004 | C7: Diurno | D7: VARRIÇÃO MANUAL DE VIAS E LOGRADOUROS PÚBLICOS - SARJETAS | E7: Diário | F7: Segunda a Domingo | G7: 6.206024 | H7: 03-0101 | I7: 45994 | J7: 245 | K7: 46017
A8: CV | B8: CV10101VJ0005 | C8: Diurno | D8: VARRIÇÃO MANUAL DE VIAS E LOGRADOUROS PÚBLICOS - SARJETAS | E8: Diário | F8: Segunda a Domingo | G8: 5.898842 | H8: 03-0057 | I8: 45994 | J8: 329 | K8: 46017
A9: CV | B9: CV10101VJ0006 | C9: Diurno | D9: VARRIÇÃO MANUAL DE VIAS E LOGRADOUROS PÚBLICOS - SARJETAS | E9: Diário | F9: Segunda a Domingo | G9: 6.124736 | H9: 03-0112 | I9: 45994 | J9: 064 | K9: 46017
A10: CV | B10: CV10101VJ0007 | C10: Diurno | D10: VARRIÇÃO MANUAL DE VIAS E LOGRADOUROS PÚBLICOS - SARJETAS | E10: Diário | F10: Segunda a Domingo | G10: 6.115814 | H10: 03-0096 | I10: 45994 | J10: 065 | K10: 46017
A11: CV | B11: CV10101VJ0008 | C11: Diurno | D11: VARRIÇÃO MANUAL DE VIAS E LOGRADOUROS PÚBLICOS - SARJETAS | E11: Diário | F11: Segunda a Domingo | G11: 6.368843 | H11: 03-0120 | I11: 45994 | J11: 196 | K11: 46017
A12: CV | B12: CV10101VJ0009 | C12: Diurno | D12: VARRIÇÃO MANUAL DE VIAS E LOGRADOUROS PÚBLICOS - SARJETAS | E12: Diário | F12: Segunda a Domingo | G12: 6.170581 | H12: 03-0102 | I12: 45994 | J12: 039 | K12: 46017
A13: CV | B13: CV10102VJ0010 | C13: Diurno | D13: VARRIÇÃO MANUAL DE VIAS E LOGRADOUROS PÚBLICOS - SARJETAS | E13: Diário 2x | F13: Segunda a Domingo | G13: 3.103363 | H13: 03-0130 | I13: 45994 | J13: 069 | K13: 46017
... A151: ST | B151: ST10203VJ0080 | C151: Diurno | D151: VARRIÇÃO MANUAL DE VIAS E LOGRADOUROS PÚBLICOS - SARJETAS | E151: Alternado | F151: Terça/Quinta/Sábado | G151: 5.919429 | H151: 03-0316 | I151: 46102 | J151: 091 | K151: 46051
A152: JT | B152: JT10101VL0001 | C152: Diurno | D152: VARRIÇÃO MANUAL DE VIAS E LOGRADOUROS PÚBLICOS - SARJETAS E CALÇADAS | E152: Diário | F152: Segunda a Domingo | G152: 5.280792 | H152: 03-0026 | I152: 46006 | J152: 201 | K152: 46028
A153: JT | B153: JT10101VL0002 | C153: Diurno | D153: VARRIÇÃO MANUAL DE VIAS E LOGRADOUROS PÚBLICOS - SARJETAS E CALÇADAS | E153: Diário | F153: Segunda a Sábado | G153: 5.127622 | H153: 03-0086 | I153: 46006 | J153: 195 | K153: 46028
A154: JT | B154: JT10102VJ0001 | C154: Diurno | D154: VARRIÇÃO MANUAL DE VIAS E LOGRADOUROS PÚBLICOS - SARJETAS | E154: Diário | F154: Segunda a Domingo | G154: 5.918848 | H154: 03-0049 | I154: 46006 | J154: 187 | K154: 46057
A155: JT | B155: JT20102VJ0001 | C155: Vespertino | D155: VARRIÇÃO MANUAL DE VIAS E LOGRADOUROS PÚBLICOS - SARJETAS | E155: Diário | F155: Segunda a Domingo | G155: 5.918848 | H155: 03-0103 | I155: 46007 | J155: 189 | K155: 46057
A156: JT | B156: JT10102VJ0002 | C156: Diurno | D156: VARRIÇÃO MANUAL DE VIAS E LOGRADOUROS PÚBLICOS - SARJETAS | E156: Diário | F156: Segunda a Domingo | G156: 5.610848 | H156: 03-0138 | I156: 46006 | J156: 321 | K156: 46057
A157: JT | B157: JT20102VJ0002 | C157: Vespertino | D157: VARRIÇÃO MANUAL DE VIAS E LOGRADOUROS PÚBLICOS - SARJETAS | E157: Diário | F157: Segunda a Domingo | G157: 5.918848 | H157: 03-0033 | I157: 46007 | J157: 199 | K157: 46057
A158: JT | B158: JT10102VJ0003 | C158: Diurno | D158: VARRIÇÃO MANUAL DE VIAS E LOGRADOUROS PÚBLICOS - SARJETAS | E158: Diário | F158: Segunda a Domingo | G158: 5.808575 | H158: 03-0023 | I158: 46006 | J158: 243 | K158: 46057
A159: JT | B159: JT20102VJ0003 | C159: Vespertino | D159: VARRIÇÃO MANUAL DE VIAS E LOGRADOUROS PÚBLICOS - SARJETAS | E159: Diário | F159: Segunda a Domingo | G159: 5.918848 | H159: 03-0059 | I159: 46007 | J159: 192 | K159: 46057
A160: JT | B160: JT10101VJ0004 | C160: Diurno | D160: VARRIÇÃO MANUAL DE VIAS E LOGRADOUROS PÚBLICOS - SARJETAS | E160: Diário | F160: Segunda a Domingo | G160: 5.971002 | H160: 03-0080 | I160: 46006 | J160: 324 | K160: 46028
A161: JT | B161: JT10202VJ0054 | C161: Diurno | D161: VARRIÇÃO MANUAL DE VIAS E LOGRADOUROS PÚBLICOS - SARJETAS | E161: Alternado | F161: Segunda/Quarta/Sexta | G161: 5.361291 | H161: 03-0005 | I161: 46007 | J161: 167 | K161: 46024
A162: JT | B162: JT10202VJ0056 | C162: Diurno | D162: VARRIÇÃO MANUAL DE VIAS E LOGRADOUROS PÚBLICOS - SARJETAS | E162: Alternado | F162: Segunda/Quarta/Sexta | G162: 5.005991 | H162: 03-0042 | I162: 46006 | J162: 158 | K162: 46024
A163: JT | B163: JT10203VJ0053 | C163: Diurno | D163: VARRIÇÃO MANUAL DE VIAS E LOGRADOUROS PÚBLICOS - SARJETAS | E163: Alternado | F163: Terça/Quinta/Sábado | G163: 5.912718 | H163: 03-0140 | I163: 46000 | J163: 194 | K163: 46029
A164: JT | B164: JT10203VJ0055 | C164: Diurno | D164: VARRIÇÃO MANUAL DE VIAS E LOGRADOUROS PÚBLICOS - SARJETAS | E164: Alternado | F164: Terça/Quinta/Sábado | G164: 5.112609 | H164: 03-0046 | I164: 46003 | J164: 191 | K164: 46025
A165: JT | B165: JT10302VJ0005 | C165: Diurno | D165: VARRIÇÃO MANUAL DE VIAS E LOGRADOUROS PÚBLICOS - SARJETAS | E165: Bissemanal | F165: Segunda/Quinta | G165: 5.995798 | H165: 03-0037 | I165: 46002 | J165: 170 | K165: 46027
A166: JT | B166: JT10302VJ0006 | C166: Diurno | D166: VARRIÇÃO MANUAL DE VIAS E LOGRADOUROS PÚBLICOS - SARJETAS | E166: Bissemanal | F166: Segunda/Quinta | G166: 6.022466 | H166: 03-0052 | I166: 46006 | J166: 325 | K166: 46027
A167: JT | B167: JT10302VJ0007 | C167: Diurno | D167: VARRIÇÃO MANUAL DE VIAS E LOGRADOUROS PÚBLICOS - SARJETAS | E167: Bissemanal | F167: Segunda/Quinta | G167: 5.965794 | H167: 03-0068 | I167: 46002 | J167: 193 | K167: 46027
A168: JT | B168: JT10302VJ0008 | C168: Diurno | D168: VARRIÇÃO MANUAL DE VIAS E LOGRADOUROS PÚBLICOS - SARJETAS | E168: Bissemanal | F168: Segunda/Quinta | G168: 6.156119 | H168: 03-0074 | I168: 46002 | J168: 175 | K168: 46027
A169: JT | B169: JT10302VJ0009 | C169: Diurno | D169: VARRIÇÃO MANUAL DE VIAS E LOGRADOUROS PÚBLICOS - SARJETAS | E169: Bissemanal | F169: Segunda/Quinta | G169: 6.149637 | H169: 03-0079 | I169: 46002 | J169: 200 | K169: 46027
A170: JT | B170: JT10302VJ0010 | C170: Diurno | D170: VARRIÇÃO MANUAL DE VIAS E LOGRADOUROS PÚBLICOS - SARJETAS | E170: Bissemanal | F170: Segunda/Quinta | G170: 6.008869 | H170: 03-0018 | I170: 46002 | J170: 328 | K170: 46027
A171: JT | B171: JT10302VJ0011 | C171: Diurno | D171: VARRIÇÃO MANUAL DE VIAS E LOGRADOUROS PÚBLICOS - SARJETAS | E171: Bissemanal | F171: Segunda/Quinta | G171: 5.968363 | H171: 03-0014 | I171: 46002 | J171: 244 | K171: 46027
A172: JT | B172: JT10302VJ0012 | C172: Diurno | D172: VARRIÇÃO MANUAL DE VIAS E LOGRADOUROS PÚBLICOS - SARJETAS | E172: Bissemanal | F172: Segunda/Quinta | G172: 6.062179 | H172: 03-0123 | I172: 46002 | J172: 307 | K172: 46027
A173: JT | B173: JT10302VJ0013 | C173: Diurno | D173: VARRIÇÃO MANUAL DE VIAS E LOGRADOUROS PÚBLICOS - SARJETAS | E173: Bissemanal | F173: Segunda/Quinta | G173: 5.964699 | H173: 03-0117 | I173: 46002 | J173: 190 | K173: 46027
A174: JT | B174: JT10302VJ0014 | C174: Diurno | D174: VARRIÇÃO MANUAL DE VIAS E LOGRADOUROS PÚBLICOS - SARJETAS | E174: Bissemanal | F174: Segunda/Quinta | G174: 6.055712 | H174: 03-0110 | I174: 46002 | J174: 188 | K174: 46030
A175: JT | B175: JT10302VJ0015 | C175: Diurno | D175: VARRIÇÃO MANUAL DE VIAS E LOGRADOUROS PÚBLICOS - SARJETAS | E175: Bissemanal | F175: Segunda/Quinta | G175: 6.057358 | H175: 03-0030 | I175: 46002 | J175: 319 | K175: 46034
A176: JT | B176: JT10302VJ0016 | C176: Diurno | D176: VARRIÇÃO MANUAL DE VIAS E LOGRADOUROS PÚBLICOS - SARJETAS | E176: Bissemanal | F176: Segunda/Quinta | G176: 5.842275 | H176: 03-0045 | I176: 46002 | J176: 308 | K176: 46030
A177: JT | B177: JT10302VJ0017 | C177: Diurno | D177: VARRIÇÃO MANUAL DE VIAS E LOGRADOUROS PÚBLICOS - SARJETAS | E177: Bissemanal | F177: Segunda/Quinta | G177: 6.007319 | H177: 03-0093 | I177: 46002 | J177: 197 | K177: 46030
...

Sheet SETORES PRAÇA
A1: SUBPREFEITURA | B1: SETOR | C1: SERVIÇO | D1: PRAÇA | E1: FREQUÊNCIA | F1: DIAS DE EXECUÇÃO | G1: KM_PROD | H1: SELIMP | I1: INSTALAÇÃO | J1: LIMPEBRAS | K1: INSTALAÇÃO
A2: CV | B2: CV10101VP0001/02/03 | C2: EQUIPE PARA VARRIÇÃO DE PRAÇAS | D2: PRAÇA LIONS CLUBE ÍMIRIM/ LARGO DO JAPONÊS/ PRAÇA DO POVO | E2: Diário | F2: Segunda a Sábado | G2: 6.819 | H2: 03-0217 | I2: 46100 | J2: 129 | K2: 46062
A3: CV | B3: CV10101VP0004 | C3: EQUIPE PARA VARRIÇÃO DE PRAÇAS | D3: PRAÇA DOM HELVÉCIO GOMES DE OLIVEIRA | E3: Diário | F3: Segunda a Sábado | G3: 0.099 | H3: 03-0213 | I3: 46100 | J3: 123 | K3: 46062
A4: CV | B4: CV10101VP0005 | C4: EQUIPE PARA VARRIÇÃO DE PRAÇAS | D4: PRAÇA MARIANO MELGAR | E4: Diário | F4: Segunda a Sábado | G4: 0.283 | H4: 03-0305 | I4: 46100 | J4: 145 | K4: 46062
A5: CV | B5: CV10101VP0006/07/08 | C5: EQUIPE PARA VARRIÇÃO DE PRAÇAS | D5: PRAÇA JOAO AZEVEDO BORGES/ PRAÇA WALDEMAR GASPAR DE OLIVEIRA/ PRAÇA GERCINO JOSE DE SOUZA | E5: Diário | F5: Segunda a Sábado | G5: 12.294 | H5: 03-0231 | I5: 46100 | J5: 030 | K5: 46062
A6: CV | B6: CV10202VP0009/10 | C6: EQUIPE PARA VARRIÇÃO DE PRAÇAS | D6: PRAÇA CRUZ DA ESPERANÇA/ PRAÇA JOAQUIM VIEIRA LOPES | E6: Alternado | F6: Segunda/Quarta/Sexta | G6: 4.21 | H6: 03-0158 | I6: 46106 | J6: 140 | K6: 46062
A7: CV | B7: CV10202VP0011 | C7: EQUIPE PARA VARRIÇÃO DE PRAÇAS | D7: PRAÇA JOÃO CABRAL REZENDE | E7: Alternado | F7: Segunda/Quarta/Sexta | G7: 3.415 | H7: 03-0296 | I7: 46106 | J7: 117 | K7: 46071
A8: CV | B8: CV10202VP0012 | C8: EQUIPE PARA VARRIÇÃO DE PRAÇAS | D8: PRAÇA 02 DE DEZEMBRO | E8: Alternado | F8: Segunda/Quarta/Sexta | G8: 2.672 | H8: 03-0294 | I8: 46106 | J8: 130 | K8: 46073
A9: CV | B9: CV10202VP0013/14 | C9: EQUIPE PARA VARRIÇÃO DE PRAÇAS | D9: PRAÇA SANTÍSSIMA TRINDADE/ PRAÇA PROFESSOR CESARINO JÚNIOR | E9: Alternado | F9: Segunda/Quarta/Sexta | G9: 7.678 | H9: 03-0230 | I9: 46106 | J9: 136 | K9: 46071
A10: CV | B10: CV10202VP0015/16 | C10: EQUIPE PARA VARRIÇÃO DE PRAÇAS | D10: RAÇA ADRIANO RIBEIRO CARDOSO/ PRAÇA MARIA HELENA DO NASCIMENTO | E10: Alternado | F10: Segunda/Quarta/Sexta | G10: 4.758 | H10: 03-0229 | I10: 46106 | J10: 100 | K10: 46071
A11: CV | B11: CV10203VP0017/18 | C11: EQUIPE PARA VARRIÇÃO DE PRAÇAS | D11: PRAÇA BENITO NICOLETTI/ PRAÇA CANAÃ | E11: Alternado | F11: Terça/Quinta/Sábado | G11: 1.341 | H11: 03-0212 | I11: 46112 | J11: 119 | K11: 46072
A12: CV | B12: CV10203VP0019 | C12: EQUIPE PARA VARRIÇÃO DE PRAÇAS | D12: PRAÇA MARIO FABRE | E12: Alternado | F12: Terça/Quinta/Sábado | G12: 0.453 | H12: 03-0145 | I12: 46100 | J12: 121 | K12: 46070
A13: CV | B13: CV10203VP0020/21 | C13: EQUIPE PARA VARRIÇÃO DE PRAÇAS | D13: PRAÇA RADIALISTA MANOEL DE NOBREGA/ PRAÇA CENTENÁRIO | E13: Alternado | F13: Terça/Quinta/Sábado | G13: 5.06 | H13: 03-0223 | I13: 46100 | J13: 113 | K13: 46070
... A15: CV | B15: CV10203VP0023 | C15: EQUIPE PARA VARRIÇÃO DE PRAÇAS | D15: PRAÇA ANTONIO FRANCO VELASCO | E15: Alternado | F15: Terça/Quinta/Sábado | G15: 0.906 | H15: 03-0306 | I15: 46100 | J15: 133 | K15: 46070
A16: ST | B16: ST10101VP0001 | C16: EQUIPE PARA VARRIÇÃO DE PRAÇAS | D16: PRAÇA ROTARY DISTRITAL | E16: Diário | F16: Segunda a Sábado | G16: 5.725
A17: ST | B17: ST10101VP0002 | C17: EQUIPE PARA VARRIÇÃO DE PRAÇAS | D17: PRAÇA AIRTON DE ABREU | E17: Diário | F17: Segunda a Sábado | G17: 1.769
A18: ST | B18: ST10101VP0003/04 | C18: EQUIPE PARA VARRIÇÃO DE PRAÇAS | D18: PRAÇA RENATO DE ARAUJO SALGADO/ PRAÇA NOSSA SENHORA DOS PRAZERES | E18: Diário | F18: Segunda a Sábado | G18: 7.707
A19: ST | B19: ST10101VP0005/06 | C19: EQUIPE PARA VARRIÇÃO DE PRAÇAS | D19: PRAÇA PAINEIRA DO CAMPO/ PRAÇA NAKHLE KHOURI GHARIB | E19: Diário | F19: Segunda a Sábado | G19: 3.247
A20: ST | B20: ST10101VP0007 | C20: EQUIPE PARA VARRIÇÃO DE PRAÇAS | D20: PÇ. DR. ANTONIO MARIA DE LAET X R. CLAUDINO INACIO JOAQUIM X R. CONEGO LADEIRA | E20: Diário | F20: Segunda a Sábado | G20: 3.65
A21: ST | B21: ST10101VP0008 | C21: EQUIPE PARA VARRIÇÃO DE PRAÇAS | D21: PRAÇA HERÓIS DA FORÇA EXPEDICIONÁRIA BRASILEIRA | E21: Diário | F21: Segunda a Sábado | G21: 9.785
A22: ST | B22: ST10101VP0009/10 | C22: EQUIPE PARA VARRIÇÃO DE PRAÇAS | D22: PRAÇA ORLANDO SILVA/ RUA NOGUEIRA ACIOLI | E22: Diário | F22: Segunda a Sábado | G22: 3.161
A23: ST | B23: ST10101VP0011/12 | C23: EQUIPE PARA VARRIÇÃO DE PRAÇAS | D23: RAÇA JOÃO DE MORAES SETÚBAL/ PRAÇA CORONEL PM PAULO DE TARSO AUGUSTO | E23: Diário | F23: Segunda a Sábado | G23: 9.612
A24: ST | B24: ST10101VP0013/14 | C24: EQUIPE PARA VARRIÇÃO DE PRAÇAS | D24: PRAÇA ROTARY DE SÃO PAULO - NORTE/ PRAÇA RUBENS FIORANTI | E24: Diário | F24: Segunda a Sábado | G24: 6.342
A25: ST | B25: ST10101VP0015 | C25: EQUIPE PARA VARRIÇÃO DE PRAÇAS | D25: PRAÇA TERMINAL RODOVIÁRIO TIETÊ | E25: Diário | F25: Segunda a Sábado | G25: 6.084
A26: ST | B26: ST10101VP0016 | C26: EQUIPE PARA VARRIÇÃO DE PRAÇAS | D26: AV. CRUZEIRO DO SUL(CANTEIRO CENTRAL) | E26: Diário | F26: Segunda a Sábado | G26: 0.729
A27: ST | B27: ST10101VP0017 | C27: EQUIPE PARA VARRIÇÃO DE PRAÇAS | D27: CANTEIRO CENTRAL AV. ZAKI NARCHI | E27: Diário | F27: Segunda a Sábado | G27: 0.88
... A33: ST | B33: ST10304VP0030 | C33: EQUIPE PARA VARRIÇÃO DE PRAÇAS | D33: PRAÇA CAETANA FARINI DE CARVALHO | E33: Bissemanal | F33: Quarta/Sábado | G33: 2.948
A34: JT | B34: JT10101VP0001 | C34: EQUIPE PARA VARRIÇÃO DE PRAÇAS | D34: PRAÇA COMANDANTE EDUARDO DE OLIVEIRA | E34: Diário | F34: Segunda a Sábado | G34: 6.43 | H34: 03-0161 | I34: 46099 | J34: 128 | K34: 46063
A35: JT | B35: JT10101VP0002/03 | C35: EQUIPE PARA VARRIÇÃO DE PRAÇAS | D35: PRAÇA JOÃO BATISTA VASQUES/ PRAÇA COMANDANTE ALBERTO DE SOUZA | E35: Diário | F35: Segunda a Sábado | G35: 5.909 | H35: 03-0153 | I35: 46099 | J35: 135 | K35: 46062
A36: JT | B36: JT10302VP0004/05 | C36: EQUIPE PARA VARRIÇÃO DE PRAÇAS | D36: PRAÇA WAGNER MACIERA/ PRAÇA MEMÓRIA DO JAÇANÃ | E36: Bissemanal | F36: Segunda/Quinta | G36: 6.025 | H36: 03-0156 | I36: 46107 | J36: 161 | K36: 46065
A37: JT | B37: JT10302VP0006/07 | C37: EQUIPE PARA VARRIÇÃO DE PRAÇAS | D37: PRAÇA ALVARO ALTAIR MARINELLI/ PRAÇA FAUSTO ANTONIO | E37: Bissemanal | F37: Segunda/Quinta | G37: 9.672 | H37: 03-0304 | I37: 46100 | J37: 125 | K37: 46065
